



--Samll Fern Tree 03
	local N = gal_ecology_trees.N

	
		return {
		size = {x = 1,y = 6,z = 1},
		data = {
			{param2 = 0,name = "gal:tree_fern_small_trunk",prob = 254},
			{param2 = 0,name = "gal:tree_fern_small_trunk",prob = 254},
			{param2 = 0,name = "gal:tree_fern_small_trunk",prob = 254},
			{param2 = 0,name = "gal:tree_fern_small_trunk",prob = 254},
			{param2 = 0,name = "gal:tree_fern_small_trunk_top",prob = 254},
			{param2 = 0,name = "gal:tree_fern_small_leaves",prob = 254}
		},
		yslice_prob = {
			{ypos = 0,prob = 254},
			{ypos = 1,prob = 127},
			{ypos = 2,prob = 254},
			{ypos = 3,prob = 127},
			{ypos = 4,prob = 254},
			{ypos = 5,prob = 254},
			{ypos = 6,prob = 254}
		}
	}
