

--Air, Lava, and Water constants used throughout schematics
		local __ = {name = "air", param2 = 0, prob = 0}
		local wt = {name = "gal:liquid_water_river_source", param2 = 0, prob = 254}
		local lv = {name = "gal:liquid_lava_source", param2 = 0, prob = 254}
		local lf = {name = "gal:liquid_lava_flowing", param2 = 0, prob = 254}
		
--Node Definitions
		local M0 = {name = "gal:stone", param2 = 0, prob = 254}
		local M1 = {name = "gal:stone_cobble", param2 = 0, prob = 254}
		local M2 = {name = "gal:stone_brick", param2 = 0, prob = 254}
		local M3 = {name = "gal:stone_block", param2 = 0, prob = 254}
		local M4 = {name = "gal:stone_stucco", param2 = 0, prob = 254}
		local M5 = {name = "stairs:slab_stonebrick", param2 = 3, prob = 254}
		local M6 = {name = "stairs:stair_cobble", param2 = 0, prob = 254}
		local M7 = {name = "stairs:slab_stonebrick", param2 = 0, prob = 254}
		local M8 = {name = "", param2 = 0, prob = 254}
		local M9 = {name = "", param2 = 0, prob = 254}
		local MX = {name = "", param2 = 4, prob = 254}
		local MZ = {name = "", param2 = 8, prob = 254}

		local N0 = {name = "gal:stone_sand", param2 = 0, prob = 254}
		local N1 = {name = "gal:sand", param2 = 0, prob = 254}
		local N2 = {name = "gal:stone_gravel", param2 = 0, prob = 254}
		local N3 = {name = "gal:stone_cobble_mossy", param2 = 0, prob = 254}
		local N4 = {name = "gal:stone_brick_mossy", param2 = 0, prob = 254}
		local N5 = {name = "gal:stone_tile", param2 = 0, prob = 254}
		local N6 = {name = "gal:stone_tile_with_dirt", param2 = 0, prob = 254}
		local N7 = {name = "gal:stone_tile_mossy", param2 = 0, prob = 254}
		local N8 = {name = "gal:stone_tile_crumbled", param2 = 0, prob = 254}
		local N9 = {name = "gal:tree_default_wood", param2 = 0, prob = 254}
		local NY = {name = "gal:tree_default_trunk", param2 = 0, prob = 254}
		local NZ = {name = "gal:tree_default_trunk", param2 = 4, prob = 254}
		local NX = {name = "gal:tree_default_trunk", param2 = 8, prob = 254}

		local S0 = {name = "gal:stone_cobble_stairs", param2 = 0, prob = 254}
		local S1 = {name = "gal:stone_cobble_stairs", param2 = 1, prob = 254}
		local S2 = {name = "gal:stone_cobble_stairs", param2 = 2, prob = 254}
		local S3 = {name = "gal:stone_cobble_stairs", param2 = 3, prob = 254}
		local S5 = {name = "gal:stone_cobble_stairs", param2 = 20, prob = 254}
		local S6 = {name = "gal:stone_cobble_stairs", param2 = 21, prob = 254}
		local S7 = {name = "gal:stone_cobble_stairs", param2 = 22, prob = 254}
		local S8 = {name = "gal:stone_cobble_stairs", param2 = 23, prob = 254}
		local SN = {name = "gal:stone_cobble_stairs", param2 = 4, prob = 254}
		local SE = {name = "gal:stone_cobble_stairs", param2 = 8, prob = 254}
		local SW = {name = "gal:stone_cobble_stairs", param2 = 12, prob = 254}
		local SS = {name = "gal:stone_cobble_stairs", param2 = 16, prob = 254}
		
		local Q0 = {name = "gal:tree_default_wood_slab", param2 = 0, prob = 254}
		local Q1 = {name = "gal:tree_default_wood_slab", param2 = 1, prob = 254}
		local Q2 = {name = "gal:tree_default_wood_slab", param2 = 2, prob = 254}
		local Q3 = {name = "gal:tree_default_wood_slab", param2 = 3, prob = 254}
		local Q5 = {name = "gal:tree_default_wood_slab", param2 = 20, prob = 254}
		local Q6 = {name = "gal:tree_default_wood_slab", param2 = 21, prob = 254}
		local Q7 = {name = "gal:tree_default_wood_slab", param2 = 22, prob = 254}
		local Q8 = {name = "gal:tree_default_wood_slab", param2 = 23, prob = 254}
		local QN = {name = "gal:tree_default_wood_slab", param2 = 4, prob = 254}
		local QE = {name = "gal:tree_default_wood_slab", param2 = 8, prob = 254}
		local QW = {name = "gal:tree_default_wood_slab", param2 = 12, prob = 254}
		local QS = {name = "gal:tree_default_wood_slab", param2 = 16, prob = 254}
		
		local O0 = {name = "gal:stone_stairs_outer", param2 = 0, prob = 254}
		local O1 = {name = "gal:stone_stairs_outer", param2 = 1, prob = 254}
		local O2 = {name = "gal:stone_stairs_outer", param2 = 2, prob = 254}
		local O3 = {name = "gal:stone_stairs_outer", param2 = 3, prob = 254}
		local O5 = {name = "gal:stone_stairs_inner", param2 = 0, prob = 254}
		local O6 = {name = "gal:stone_stairs_inner", param2 = 1, prob = 254}
		local O7 = {name = "gal:stone_stairs_inner", param2 = 2, prob = 254}
		local O8 = {name = "gal:stone_stairs_inner", param2 = 3, prob = 254}

		local JW = {name = "gal:tree_jungle_01_wood", param2 = 0, prob = 254}
		local PW = {name = "gal:tree_pine_01_wood", param2 = 0, prob = 254}
		

		local DD = {name = "gal:dirt", param2 = 0, prob = 254}
		local DG = {name = "gal:dirt_with_grass", param2 = 0, prob = 254}
		local GR = {name = "gal:dirt_with_grass", param2 = 0, prob = 254}
		local G1 = {name = "gal:glass", param2 = 0, prob = 254}

		local FF = {name = "gal:dirt_with_soil_wet", param2 = 0, prob = 254}
		local CC = {name = "gal:plant_corn_5", param2 = 0, prob = 254}
		
		
		local F0 = {name = "lib_forge:furnace", param2 = 0, prob = 254}
		local F1 = {name = "lib_forge:furnace", param2 = 1, prob = 254}
		local F2 = {name = "lib_forge:furnace", param2 = 2, prob = 254}
		local F3 = {name = "lib_forge:furnace", param2 = 3, prob = 254}

		local C0 = {name = "lib_chests:chest", param2 = 0, prob = 254}
		local C1 = {name = "lib_chests:chest", param2 = 1, prob = 254}
		local C2 = {name = "lib_chests:chest", param2 = 2, prob = 254}
		local C3 = {name = "lib_chests:chest", param2 = 3, prob = 254}

		local L0 = {name = "default:ladder_wood", param2 = 0, prob = 254}
		local L1 = {name = "default:ladder_wood", param2 = 1, prob = 254}
		local L2 = {name = "default:ladder_wood", param2 = 2, prob = 254}
		local L3 = {name = "default:ladder_wood", param2 = 3, prob = 254}
		local L4 = {name = "default:ladder_wood", param2 = 4, prob = 254}
		local L5 = {name = "default:ladder_wood", param2 = 5, prob = 254}

		local DR = {name = "gal:tree_default_wood_door_centered_300_height_150_width_right", param2 = 1, prob = 254}
		local DL = {name = "gal:tree_default_wood_door_centered_300_height_150_width", param2 = 1, prob = 254}
		local D0 = {name = "gal:tree_default_wood_door_centered_with_window", param2 = 0, prob = 254}
		local D1 = {name = "gal:tree_default_wood_door_centered_with_window", param2 = 1, prob = 254}
		local D2 = {name = "gal:tree_default_wood_door_centered_with_window", param2 = 2, prob = 254}
		local D3 = {name = "gal:tree_default_wood_door_centered_with_window", param2 = 3, prob = 254}
		local D5 = {name = "gal:tree_default_wood_trapdoor_with_window", param2 = 0, prob = 254}
		local D6 = {name = "gal:tree_default_wood_trapdoor_with_window", param2 = 1, prob = 254}
		local D7 = {name = "gal:tree_default_wood_trapdoor_with_window", param2 = 2, prob = 254}
		local D8 = {name = "gal:tree_default_wood_trapdoor_with_window", param2 = 3, prob = 254}

		local TC = {name = "torch:torch_ceiling", param2 = 0, prob = 254}
		local TT = {name = "torch:torch", param2 = 1, prob = 254}
		local T1 = {name = "torch:torch_wall", param2 = 1, prob = 254}
		local T2 = {name = "torch:torch_wall", param2 = 2, prob = 254}
		local T3 = {name = "torch:torch_wall", param2 = 3, prob = 254}
		local T4 = {name = "torch:torch_wall", param2 = 4, prob = 254}
		local T5 = {name = "torch:torch_wall", param2 = 5, prob = 254}
		local T6 = {name = "decoblocks:lantern_wall", param2 = 2, prob = 254}
		local T7 = {name = "decoblocks:lantern_wall", param2 = 3, prob = 254}
		local T8 = {name = "decoblocks:lantern_wall", param2 = 4, prob = 254}
		local T9 = {name = "decoblocks:lantern_wall", param2 = 5, prob = 254}
		local T0 = {name = "decoblocks:lantern_ceiling", param2 = 0, prob = 254}

		local A0 = {name = "lib_tools:anvil", param2 = 0, prob = 254}
		local A1 = {name = "lib_tools:anvil", param2 = 1, prob = 254}
		local A2 = {name = "lib_tools:anvil", param2 = 2, prob = 254}
		local A3 = {name = "lib_tools:anvil", param2 = 3, prob = 254}
		local AA = {name = "decoblocks:altar", param2 = 2, prob = 254}

		local B0 = {name = "beds:bed_bottom", param2 = 0, prob = 254}
		local B1 = {name = "beds:bed_bottom", param2 = 1, prob = 254}
		local B2 = {name = "beds:bed_bottom", param2 = 2, prob = 254}
		local B3 = {name = "beds:bed_bottom", param2 = 3, prob = 254}
		local B5 = {name = "beds:bed_top", param2 = 0, prob = 254}
		local B6 = {name = "beds:bed_top", param2 = 1, prob = 254}
		local B7 = {name = "beds:bed_top", param2 = 2, prob = 254}
		local B8 = {name = "beds:bed_top", param2 = 3, prob = 254}
		local BN = {name = "lib_books:bookshelf", param2 = 0, prob = 254}
		local BE = {name = "lib_books:bookshelf", param2 = 1, prob = 254}
		local BS = {name = "lib_books:bookshelf", param2 = 2, prob = 254}
		local BW = {name = "lib_books:bookshelf", param2 = 3, prob = 254}

		local RB = {name = "lib_tools:ropebox", param2 = 3, prob = 254}
		local RP = {name = "lib_tools:box_rope", param2 = 0, prob = 254}

		local R1 = {name = "cottages:roof_wood", param2 = 1, prob = 254}
		local R3 = {name = "cottages:roof_wood", param2 = 3, prob = 254}
		local R5 = {name = "cottages:roof_connector_wood", param2 = 1, prob = 254}
		local R7 = {name = "cottages:roof_connector_wood", param2 = 3, prob = 254}

		local X0 = {name = "xpanes:bar_flat", param2 = 0, prob = 254}
		local X1 = {name = "xpanes:bar_flat", param2 = 1, prob = 254}
		local X2 = {name = "xpanes:bar_flat", param2 = 2, prob = 254}
		local X3 = {name = "xpanes:bar_flat", param2 = 3, prob = 254}
		local X5 = {name = "xpanes:framed_pane_flat", param2 = 0, prob = 254}
		local X6 = {name = "xpanes:framed_pane_flat", param2 = 1, prob = 254}
		local X7 = {name = "xpanes:framed_pane_flat", param2 = 2, prob = 254}
		local X8 = {name = "xpanes:framed_pane_flat", param2 = 3, prob = 254}

		local Z1 = {name = "lib_tools:cauldron_empty", param2 = 0, prob = 254}
		local Z2 = {name = "gal:tree_default_wood_table_basic_01", param2 = 0, prob = 254}
		local Z3 = {name = "gal:metal_steel_block", param2 = 0, prob = 254}
		local Z4 = {name = "xpanes:bar_flat", param2 = 1, prob = 254}
		local Z5 = {name = "mg_villages:mob_workplace_marker", param2 = 0, prob = 254}
		local Z6 = {name = "cottages:shelf", param2 = 1, prob = 254}
		local Z7 = {name = "cottages:shelf", param2 = 3, prob = 254}
		local Z8 = {name = "cottages:table", param2 = 2, prob = 254}

		local I0 = {name = "air",param2 = 0,prob = 254}
		local I1 = {name = "air",param2 = 1,prob = 254}
		local I2 = {name = "air",param2 = 2,prob = 254}
		local I3 = {name = "air",param2 = 3,prob = 254}
		local I4 = {name = "",param2 = 0,prob = 254}
		local I5 = {name = "lib_tools:draft_table",param2 = 0,prob = 254}
		local I6 = {name = "decoblocks:vase",param2 = 0,prob = 254}
		local I7 = {name = "air",param2 = 0,prob = 254}
		local I8 = {name = "",param2 = 0,prob = 254}
		local I9 = {name = "",param2 = 0,prob = 254}

		local II = {name = "gal:tree_default_wood_fence",param2 = 0,prob = 254}

		local le_temp_schem
		


--Wagon 1 Schematic
	le_temp_schem = {
	size = {x = 5,y = 4,z = 5},
	yslice_prob = {
		{
			ypos = 0,
			prob = 254
		},
		{
			ypos = 1,
			prob = 254
		},
		{
			ypos = 2,
			prob = 254
		},
		{
			ypos = 3,
			prob = 254
		}
	},
	data = {
		{
			param2 = 0,
			name = "default:dirt_with_grass",
			prob = 254
		},
		{
			param2 = 0,
			name = "default:dirt_with_grass",
			prob = 254
		},
		{
			param2 = 0,
			name = "default:dirt_with_grass",
			prob = 254
		},
		{
			param2 = 0,
			name = "default:dirt_with_grass",
			prob = 254
		},
		{
			param2 = 0,
			name = "default:dirt_with_grass",
			prob = 254
		},
		{
			param2 = 0,
			name = "air",
			prob = 254
		},
		{
			param2 = 0,
			name = "air",
			prob = 254
		},
		{
			param2 = 0,
			name = "air",
			prob = 254
		},
		{
			param2 = 0,
			name = "air",
			prob = 254
		},
		{
			param2 = 0,
			name = "air",
			prob = 254
		},
		{
			param2 = 0,
			name = "air",
			prob = 254
		},
		{
			param2 = 0,
			name = "air",
			prob = 254
		},
		{
			param2 = 0,
			name = "air",
			prob = 254
		},
		{
			param2 = 0,
			name = "air",
			prob = 254
		},
		{
			param2 = 0,
			name = "air",
			prob = 254
		},
		{
			param2 = 0,
			name = "air",
			prob = 254
		},
		{
			param2 = 0,
			name = "air",
			prob = 254
		},
		{
			param2 = 0,
			name = "air",
			prob = 254
		},
		{
			param2 = 0,
			name = "air",
			prob = 254
		},
		{
			param2 = 0,
			name = "air",
			prob = 254
		},
		{
			param2 = 0,
			name = "default:dirt_with_grass",
			prob = 254
		},
		{
			param2 = 0,
			name = "default:dirt_with_grass",
			prob = 254
		},
		{
			param2 = 0,
			name = "default:dirt_with_grass",
			prob = 254
		},
		{
			param2 = 0,
			name = "default:dirt_with_grass",
			prob = 254
		},
		{
			param2 = 0,
			name = "default:dirt_with_grass",
			prob = 254
		},
		{
			param2 = 0,
			name = "air",
			prob = 254
		},
		{
			param2 = 4,
			name = "cottages:wagon_wheel",
			prob = 254
		},
		{
			param2 = 0,
			name = "air",
			prob = 254
		},
		{
			param2 = 4,
			name = "cottages:wagon_wheel",
			prob = 254
		},
		{
			param2 = 0,
			name = "air",
			prob = 254
		},
		{
			param2 = 0,
			name = "air",
			prob = 254
		},
		{
			param2 = 0,
			name = "air",
			prob = 254
		},
		{
			param2 = 10,
			name = "cottages:hatch_wood",
			prob = 254
		},
		{
			param2 = 10,
			name = "cottages:hatch_wood",
			prob = 254
		},
		{
			param2 = 0,
			name = "air",
			prob = 254
		},
		{
			param2 = 0,
			name = "air",
			prob = 254
		},
		{
			param2 = 0,
			name = "air",
			prob = 254
		},
		{
			param2 = 0,
			name = "air",
			prob = 254
		},
		{
			param2 = 0,
			name = "air",
			prob = 254
		},
		{
			param2 = 0,
			name = "air",
			prob = 254
		},
		{
			param2 = 0,
			name = "default:dirt_with_grass",
			prob = 254
		},
		{
			param2 = 0,
			name = "default:dirt_with_grass",
			prob = 254
		},
		{
			param2 = 0,
			name = "default:dirt_with_grass",
			prob = 254
		},
		{
			param2 = 0,
			name = "default:dirt_with_grass",
			prob = 254
		},
		{
			param2 = 0,
			name = "default:dirt_with_grass",
			prob = 254
		},
		{
			param2 = 0,
			name = "air",
			prob = 254
		},
		{
			param2 = 23,
			name = "cottages:bench",
			prob = 254
		},
		{
			param2 = 0,
			name = "air",
			prob = 254
		},
		{
			param2 = 21,
			name = "cottages:bench",
			prob = 254
		},
		{
			param2 = 0,
			name = "air",
			prob = 254
		},
		{
			param2 = 0,
			name = "air",
			prob = 254
		},
		{
			param2 = 20,
			name = "cottages:table",
			prob = 254
		},
		{
			param2 = 0,
			name = "cottages:straw_bale",
			prob = 254
		},
		{
			param2 = 0,
			name = "cottages:straw_bale",
			prob = 254
		},
		{
			param2 = 0,
			name = "air",
			prob = 254
		},
		{
			param2 = 0,
			name = "air",
			prob = 254
		},
		{
			param2 = 0,
			name = "air",
			prob = 254
		},
		{
			param2 = 0,
			name = "cottages:straw_bale",
			prob = 254
		},
		{
			param2 = 0,
			name = "cottages:straw_bale",
			prob = 254
		},
		{
			param2 = 0,
			name = "air",
			prob = 254
		},
		{
			param2 = 0,
			name = "default:dirt_with_grass",
			prob = 254
		},
		{
			param2 = 0,
			name = "default:dirt_with_grass",
			prob = 254
		},
		{
			param2 = 0,
			name = "default:dirt_with_grass",
			prob = 254
		},
		{
			param2 = 0,
			name = "default:dirt_with_grass",
			prob = 254
		},
		{
			param2 = 0,
			name = "default:dirt_with_grass",
			prob = 254
		},
		{
			param2 = 0,
			name = "air",
			prob = 254
		},
		{
			param2 = 5,
			name = "cottages:wagon_wheel",
			prob = 254
		},
		{
			param2 = 0,
			name = "air",
			prob = 254
		},
		{
			param2 = 5,
			name = "cottages:wagon_wheel",
			prob = 254
		},
		{
			param2 = 0,
			name = "air",
			prob = 254
		},
		{
			param2 = 0,
			name = "air",
			prob = 254
		},
		{
			param2 = 0,
			name = "air",
			prob = 254
		},
		{
			param2 = 4,
			name = "cottages:hatch_wood",
			prob = 254
		},
		{
			param2 = 4,
			name = "cottages:hatch_wood",
			prob = 254
		},
		{
			param2 = 0,
			name = "air",
			prob = 254
		},
		{
			param2 = 0,
			name = "air",
			prob = 254
		},
		{
			param2 = 0,
			name = "air",
			prob = 254
		},
		{
			param2 = 0,
			name = "air",
			prob = 254
		},
		{
			param2 = 0,
			name = "air",
			prob = 254
		},
		{
			param2 = 0,
			name = "air",
			prob = 254
		},
		{
			param2 = 0,
			name = "default:dirt_with_grass",
			prob = 254
		},
		{
			param2 = 0,
			name = "default:dirt_with_grass",
			prob = 254
		},
		{
			param2 = 0,
			name = "default:dirt_with_grass",
			prob = 254
		},
		{
			param2 = 0,
			name = "default:dirt_with_grass",
			prob = 254
		},
		{
			param2 = 0,
			name = "default:dirt_with_grass",
			prob = 254
		},
		{
			param2 = 0,
			name = "air",
			prob = 254
		},
		{
			param2 = 0,
			name = "air",
			prob = 254
		},
		{
			param2 = 0,
			name = "air",
			prob = 254
		},
		{
			param2 = 0,
			name = "air",
			prob = 254
		},
		{
			param2 = 0,
			name = "air",
			prob = 254
		},
		{
			param2 = 0,
			name = "air",
			prob = 254
		},
		{
			param2 = 0,
			name = "air",
			prob = 254
		},
		{
			param2 = 0,
			name = "air",
			prob = 254
		},
		{
			param2 = 0,
			name = "air",
			prob = 254
		},
		{
			param2 = 0,
			name = "air",
			prob = 254
		},
		{
			param2 = 0,
			name = "air",
			prob = 254
		},
		{
			param2 = 0,
			name = "air",
			prob = 254
		},
		{
			param2 = 0,
			name = "air",
			prob = 254
		},
		{
			param2 = 0,
			name = "air",
			prob = 254
		},
		{
			param2 = 0,
			name = "air",
			prob = 254
		}
	}
}
lib_towns.schematics["schem_bldg_cottages_wagon_1_x5_y4_z5_r000"] = le_temp_schem

--Wagon 2 Schematic
	le_temp_schem = {
	size = {x = 6,y = 5,z = 5},
	yslice_prob = {
		{
			ypos = 0,
			prob = 254
		},
		{
			ypos = 1,
			prob = 254
		},
		{
			ypos = 2,
			prob = 254
		},
		{
			ypos = 3,
			prob = 254
		},
		{
			ypos = 4,
			prob = 254
		}
	},
	data = {
		{
			param2 = 0,
			name = "default:dirt_with_grass",
			prob = 254
		},
		{
			param2 = 0,
			name = "default:dirt_with_grass",
			prob = 254
		},
		{
			param2 = 0,
			name = "default:dirt_with_grass",
			prob = 254
		},
		{
			param2 = 0,
			name = "default:dirt_with_grass",
			prob = 254
		},
		{
			param2 = 0,
			name = "default:dirt_with_grass",
			prob = 254
		},
		{
			param2 = 0,
			name = "default:dirt_with_grass",
			prob = 254
		},
		{
			param2 = 0,
			name = "air",
			prob = 254
		},
		{
			param2 = 0,
			name = "air",
			prob = 254
		},
		{
			param2 = 0,
			name = "air",
			prob = 254
		},
		{
			param2 = 0,
			name = "air",
			prob = 254
		},
		{
			param2 = 0,
			name = "air",
			prob = 254
		},
		{
			param2 = 0,
			name = "air",
			prob = 254
		},
		{
			param2 = 0,
			name = "air",
			prob = 254
		},
		{
			param2 = 0,
			name = "air",
			prob = 254
		},
		{
			param2 = 0,
			name = "air",
			prob = 254
		},
		{
			param2 = 0,
			name = "air",
			prob = 254
		},
		{
			param2 = 0,
			name = "air",
			prob = 254
		},
		{
			param2 = 0,
			name = "air",
			prob = 254
		},
		{
			param2 = 0,
			name = "air",
			prob = 254
		},
		{
			param2 = 0,
			name = "air",
			prob = 254
		},
		{
			param2 = 0,
			name = "air",
			prob = 254
		},
		{
			param2 = 0,
			name = "air",
			prob = 254
		},
		{
			param2 = 0,
			name = "air",
			prob = 254
		},
		{
			param2 = 0,
			name = "air",
			prob = 254
		},
		{
			param2 = 0,
			name = "air",
			prob = 254
		},
		{
			param2 = 0,
			name = "air",
			prob = 254
		},
		{
			param2 = 0,
			name = "air",
			prob = 254
		},
		{
			param2 = 0,
			name = "air",
			prob = 254
		},
		{
			param2 = 0,
			name = "air",
			prob = 254
		},
		{
			param2 = 0,
			name = "air",
			prob = 254
		},
		{
			param2 = 0,
			name = "default:dirt_with_grass",
			prob = 254
		},
		{
			param2 = 0,
			name = "default:dirt_with_grass",
			prob = 254
		},
		{
			param2 = 0,
			name = "default:dirt_with_grass",
			prob = 254
		},
		{
			param2 = 0,
			name = "default:dirt_with_grass",
			prob = 254
		},
		{
			param2 = 0,
			name = "default:dirt_with_grass",
			prob = 254
		},
		{
			param2 = 0,
			name = "default:dirt_with_grass",
			prob = 254
		},
		{
			param2 = 0,
			name = "air",
			prob = 254
		},
		{
			param2 = 4,
			name = "cottages:wagon_wheel",
			prob = 254
		},
		{
			param2 = 0,
			name = "air",
			prob = 254
		},
		{
			param2 = 4,
			name = "cottages:wagon_wheel",
			prob = 254
		},
		{
			param2 = 0,
			name = "air",
			prob = 254
		},
		{
			param2 = 0,
			name = "air",
			prob = 254
		},
		{
			param2 = 0,
			name = "air",
			prob = 254
		},
		{
			param2 = 0,
			name = "air",
			prob = 254
		},
		{
			param2 = 0,
			name = "cottages:fence_small",
			prob = 254
		},
		{
			param2 = 0,
			name = "cottages:fence_small",
			prob = 254
		},
		{
			param2 = 0,
			name = "air",
			prob = 254
		},
		{
			param2 = 0,
			name = "air",
			prob = 254
		},
		{
			param2 = 0,
			name = "air",
			prob = 254
		},
		{
			param2 = 0,
			name = "air",
			prob = 254
		},
		{
			param2 = 0,
			name = "air",
			prob = 254
		},
		{
			param2 = 0,
			name = "air",
			prob = 254
		},
		{
			param2 = 0,
			name = "air",
			prob = 254
		},
		{
			param2 = 0,
			name = "air",
			prob = 254
		},
		{
			param2 = 0,
			name = "air",
			prob = 254
		},
		{
			param2 = 0,
			name = "air",
			prob = 254
		},
		{
			param2 = 0,
			name = "air",
			prob = 254
		},
		{
			param2 = 0,
			name = "air",
			prob = 254
		},
		{
			param2 = 0,
			name = "air",
			prob = 254
		},
		{
			param2 = 0,
			name = "air",
			prob = 254
		},
		{
			param2 = 0,
			name = "default:dirt_with_grass",
			prob = 254
		},
		{
			param2 = 0,
			name = "default:dirt_with_grass",
			prob = 254
		},
		{
			param2 = 0,
			name = "default:dirt_with_grass",
			prob = 254
		},
		{
			param2 = 0,
			name = "default:dirt_with_grass",
			prob = 254
		},
		{
			param2 = 0,
			name = "default:dirt_with_grass",
			prob = 254
		},
		{
			param2 = 0,
			name = "default:dirt_with_grass",
			prob = 254
		},
		{
			param2 = 0,
			name = "air",
			prob = 254
		},
		{
			param2 = 23,
			name = "cottages:bench",
			prob = 254
		},
		{
			param2 = 0,
			name = "air",
			prob = 254
		},
		{
			param2 = 21,
			name = "cottages:bench",
			prob = 254
		},
		{
			param2 = 21,
			name = "cottages:hatch_wood",
			prob = 254
		},
		{
			param2 = 0,
			name = "air",
			prob = 254
		},
		{
			param2 = 0,
			name = "air",
			prob = 254
		},
		{
			param2 = 20,
			name = "cottages:table",
			prob = 254
		},
		{
			param2 = 0,
			name = "cottages:straw_bale",
			prob = 254
		},
		{
			param2 = 0,
			name = "cottages:straw_bale",
			prob = 254
		},
		{
			param2 = 0,
			name = "cottages:straw_bale",
			prob = 254
		},
		{
			param2 = 0,
			name = "air",
			prob = 254
		},
		{
			param2 = 0,
			name = "air",
			prob = 254
		},
		{
			param2 = 0,
			name = "air",
			prob = 254
		},
		{
			param2 = 0,
			name = "cottages:straw_bale",
			prob = 254
		},
		{
			param2 = 0,
			name = "cottages:straw_bale",
			prob = 254
		},
		{
			param2 = 0,
			name = "cottages:straw_bale",
			prob = 254
		},
		{
			param2 = 0,
			name = "air",
			prob = 254
		},
		{
			param2 = 0,
			name = "air",
			prob = 254
		},
		{
			param2 = 0,
			name = "air",
			prob = 254
		},
		{
			param2 = 0,
			name = "air",
			prob = 254
		},
		{
			param2 = 0,
			name = "cottages:straw_bale",
			prob = 254
		},
		{
			param2 = 0,
			name = "cottages:straw_bale",
			prob = 254
		},
		{
			param2 = 0,
			name = "air",
			prob = 254
		},
		{
			param2 = 0,
			name = "default:dirt_with_grass",
			prob = 254
		},
		{
			param2 = 0,
			name = "default:dirt_with_grass",
			prob = 254
		},
		{
			param2 = 0,
			name = "default:dirt_with_grass",
			prob = 254
		},
		{
			param2 = 0,
			name = "default:dirt_with_grass",
			prob = 254
		},
		{
			param2 = 0,
			name = "default:dirt_with_grass",
			prob = 254
		},
		{
			param2 = 0,
			name = "default:dirt_with_grass",
			prob = 254
		},
		{
			param2 = 0,
			name = "air",
			prob = 254
		},
		{
			param2 = 5,
			name = "cottages:wagon_wheel",
			prob = 254
		},
		{
			param2 = 0,
			name = "air",
			prob = 254
		},
		{
			param2 = 5,
			name = "cottages:wagon_wheel",
			prob = 254
		},
		{
			param2 = 0,
			name = "air",
			prob = 254
		},
		{
			param2 = 0,
			name = "air",
			prob = 254
		},
		{
			param2 = 0,
			name = "air",
			prob = 254
		},
		{
			param2 = 0,
			name = "air",
			prob = 254
		},
		{
			param2 = 2,
			name = "cottages:fence_small",
			prob = 254
		},
		{
			param2 = 2,
			name = "cottages:fence_small",
			prob = 254
		},
		{
			param2 = 0,
			name = "air",
			prob = 254
		},
		{
			param2 = 0,
			name = "air",
			prob = 254
		},
		{
			param2 = 0,
			name = "air",
			prob = 254
		},
		{
			param2 = 0,
			name = "air",
			prob = 254
		},
		{
			param2 = 0,
			name = "air",
			prob = 254
		},
		{
			param2 = 0,
			name = "air",
			prob = 254
		},
		{
			param2 = 0,
			name = "air",
			prob = 254
		},
		{
			param2 = 0,
			name = "air",
			prob = 254
		},
		{
			param2 = 0,
			name = "air",
			prob = 254
		},
		{
			param2 = 0,
			name = "air",
			prob = 254
		},
		{
			param2 = 0,
			name = "air",
			prob = 254
		},
		{
			param2 = 0,
			name = "air",
			prob = 254
		},
		{
			param2 = 0,
			name = "air",
			prob = 254
		},
		{
			param2 = 0,
			name = "air",
			prob = 254
		},
		{
			param2 = 0,
			name = "default:dirt_with_grass",
			prob = 254
		},
		{
			param2 = 0,
			name = "default:dirt_with_grass",
			prob = 254
		},
		{
			param2 = 0,
			name = "default:dirt_with_grass",
			prob = 254
		},
		{
			param2 = 0,
			name = "default:dirt_with_grass",
			prob = 254
		},
		{
			param2 = 0,
			name = "default:dirt_with_grass",
			prob = 254
		},
		{
			param2 = 0,
			name = "default:dirt_with_grass",
			prob = 254
		},
		{
			param2 = 0,
			name = "air",
			prob = 254
		},
		{
			param2 = 0,
			name = "air",
			prob = 254
		},
		{
			param2 = 0,
			name = "air",
			prob = 254
		},
		{
			param2 = 0,
			name = "air",
			prob = 254
		},
		{
			param2 = 0,
			name = "air",
			prob = 254
		},
		{
			param2 = 0,
			name = "air",
			prob = 254
		},
		{
			param2 = 0,
			name = "air",
			prob = 254
		},
		{
			param2 = 0,
			name = "air",
			prob = 254
		},
		{
			param2 = 0,
			name = "air",
			prob = 254
		},
		{
			param2 = 0,
			name = "air",
			prob = 254
		},
		{
			param2 = 0,
			name = "air",
			prob = 254
		},
		{
			param2 = 0,
			name = "air",
			prob = 254
		},
		{
			param2 = 0,
			name = "air",
			prob = 254
		},
		{
			param2 = 0,
			name = "air",
			prob = 254
		},
		{
			param2 = 0,
			name = "air",
			prob = 254
		},
		{
			param2 = 0,
			name = "air",
			prob = 254
		},
		{
			param2 = 0,
			name = "air",
			prob = 254
		},
		{
			param2 = 0,
			name = "air",
			prob = 254
		},
		{
			param2 = 0,
			name = "air",
			prob = 254
		},
		{
			param2 = 0,
			name = "air",
			prob = 254
		},
		{
			param2 = 0,
			name = "air",
			prob = 254
		},
		{
			param2 = 0,
			name = "air",
			prob = 254
		},
		{
			param2 = 0,
			name = "air",
			prob = 254
		},
		{
			param2 = 0,
			name = "air",
			prob = 254
		}
	}
}
lib_towns.schematics["schem_bldg_cottages_wagon_2_x6_y5_z5_r000"] = le_temp_schem

--Wagon 3 Schematic
	le_temp_schem = {
	size = {x = 5,y = 3,z = 5},
	yslice_prob = {
		{
			ypos = 0,
			prob = 254
		},
		{
			ypos = 1,
			prob = 254
		},
		{
			ypos = 2,
			prob = 254
		}
	},
	data = {
		{
			param2 = 0,
			name = "default:dirt_with_grass",
			prob = 254
		},
		{
			param2 = 0,
			name = "default:dirt_with_grass",
			prob = 254
		},
		{
			param2 = 0,
			name = "default:dirt_with_grass",
			prob = 254
		},
		{
			param2 = 0,
			name = "default:dirt_with_grass",
			prob = 254
		},
		{
			param2 = 0,
			name = "default:dirt_with_grass",
			prob = 254
		},
		{
			param2 = 0,
			name = "air",
			prob = 254
		},
		{
			param2 = 0,
			name = "air",
			prob = 254
		},
		{
			param2 = 0,
			name = "air",
			prob = 254
		},
		{
			param2 = 0,
			name = "air",
			prob = 254
		},
		{
			param2 = 0,
			name = "air",
			prob = 254
		},
		{
			param2 = 0,
			name = "air",
			prob = 254
		},
		{
			param2 = 0,
			name = "air",
			prob = 254
		},
		{
			param2 = 0,
			name = "air",
			prob = 254
		},
		{
			param2 = 0,
			name = "air",
			prob = 254
		},
		{
			param2 = 0,
			name = "air",
			prob = 254
		},
		{
			param2 = 0,
			name = "default:dirt_with_grass",
			prob = 254
		},
		{
			param2 = 0,
			name = "default:dirt_with_grass",
			prob = 254
		},
		{
			param2 = 0,
			name = "default:dirt_with_grass",
			prob = 254
		},
		{
			param2 = 0,
			name = "default:dirt_with_grass",
			prob = 254
		},
		{
			param2 = 0,
			name = "default:dirt_with_grass",
			prob = 254
		},
		{
			param2 = 0,
			name = "air",
			prob = 254
		},
		{
			param2 = 4,
			name = "cottages:wagon_wheel",
			prob = 254
		},
		{
			param2 = 0,
			name = "air",
			prob = 254
		},
		{
			param2 = 4,
			name = "cottages:wagon_wheel",
			prob = 254
		},
		{
			param2 = 0,
			name = "air",
			prob = 254
		},
		{
			param2 = 0,
			name = "air",
			prob = 254
		},
		{
			param2 = 0,
			name = "air",
			prob = 254
		},
		{
			param2 = 0,
			name = "cottages:fence_small",
			prob = 254
		},
		{
			param2 = 0,
			name = "cottages:fence_small",
			prob = 254
		},
		{
			param2 = 0,
			name = "air",
			prob = 254
		},
		{
			param2 = 0,
			name = "default:dirt_with_grass",
			prob = 254
		},
		{
			param2 = 0,
			name = "default:dirt_with_grass",
			prob = 254
		},
		{
			param2 = 0,
			name = "default:dirt_with_grass",
			prob = 254
		},
		{
			param2 = 0,
			name = "default:dirt_with_grass",
			prob = 254
		},
		{
			param2 = 0,
			name = "default:dirt_with_grass",
			prob = 254
		},
		{
			param2 = 0,
			name = "air",
			prob = 254
		},
		{
			param2 = 23,
			name = "cottages:bench",
			prob = 254
		},
		{
			param2 = 0,
			name = "air",
			prob = 254
		},
		{
			param2 = 21,
			name = "cottages:bench",
			prob = 254
		},
		{
			param2 = 0,
			name = "air",
			prob = 254
		},
		{
			param2 = 0,
			name = "air",
			prob = 254
		},
		{
			param2 = 1,
			name = "cottages:bench",
			prob = 254
		},
		{
			param2 = 3,
			name = "cottages:hatch_wood",
			prob = 254
		},
		{
			param2 = 3,
			name = "cottages:hatch_wood",
			prob = 254
		},
		{
			param2 = 0,
			name = "air",
			prob = 254
		},
		{
			param2 = 0,
			name = "default:dirt_with_grass",
			prob = 254
		},
		{
			param2 = 0,
			name = "default:dirt_with_grass",
			prob = 254
		},
		{
			param2 = 0,
			name = "default:dirt_with_grass",
			prob = 254
		},
		{
			param2 = 0,
			name = "default:dirt_with_grass",
			prob = 254
		},
		{
			param2 = 0,
			name = "default:dirt_with_grass",
			prob = 254
		},
		{
			param2 = 0,
			name = "air",
			prob = 254
		},
		{
			param2 = 5,
			name = "cottages:wagon_wheel",
			prob = 254
		},
		{
			param2 = 0,
			name = "air",
			prob = 254
		},
		{
			param2 = 5,
			name = "cottages:wagon_wheel",
			prob = 254
		},
		{
			param2 = 0,
			name = "air",
			prob = 254
		},
		{
			param2 = 0,
			name = "air",
			prob = 254
		},
		{
			param2 = 0,
			name = "air",
			prob = 254
		},
		{
			param2 = 2,
			name = "cottages:fence_small",
			prob = 254
		},
		{
			param2 = 2,
			name = "cottages:fence_small",
			prob = 254
		},
		{
			param2 = 0,
			name = "air",
			prob = 254
		},
		{
			param2 = 0,
			name = "default:dirt_with_grass",
			prob = 254
		},
		{
			param2 = 0,
			name = "default:dirt_with_grass",
			prob = 254
		},
		{
			param2 = 0,
			name = "default:dirt_with_grass",
			prob = 254
		},
		{
			param2 = 0,
			name = "default:dirt_with_grass",
			prob = 254
		},
		{
			param2 = 0,
			name = "default:dirt_with_grass",
			prob = 254
		},
		{
			param2 = 0,
			name = "air",
			prob = 254
		},
		{
			param2 = 0,
			name = "air",
			prob = 254
		},
		{
			param2 = 0,
			name = "air",
			prob = 254
		},
		{
			param2 = 0,
			name = "air",
			prob = 254
		},
		{
			param2 = 0,
			name = "air",
			prob = 254
		},
		{
			param2 = 0,
			name = "air",
			prob = 254
		},
		{
			param2 = 0,
			name = "air",
			prob = 254
		},
		{
			param2 = 0,
			name = "air",
			prob = 254
		},
		{
			param2 = 0,
			name = "air",
			prob = 254
		},
		{
			param2 = 0,
			name = "air",
			prob = 254
		}
	}
}
lib_towns.schematics["schem_bldg_cottages_wagon_3_x5_y3_z5_r000"] = le_temp_schem

--Wagon 4 Schematic
	le_temp_schem = {
	size = {x = 5,y = 3,z = 5},
	yslice_prob = {
		{
			ypos = 0,
			prob = 254
		},
		{
			ypos = 1,
			prob = 254
		},
		{
			ypos = 2,
			prob = 254
		}
	},
	data = {
		{
			param2 = 0,
			name = "default:dirt_with_grass",
			prob = 254
		},
		{
			param2 = 0,
			name = "default:dirt_with_grass",
			prob = 254
		},
		{
			param2 = 0,
			name = "default:dirt_with_grass",
			prob = 254
		},
		{
			param2 = 0,
			name = "default:dirt_with_grass",
			prob = 254
		},
		{
			param2 = 0,
			name = "default:dirt_with_grass",
			prob = 254
		},
		{
			param2 = 0,
			name = "air",
			prob = 254
		},
		{
			param2 = 0,
			name = "air",
			prob = 254
		},
		{
			param2 = 0,
			name = "air",
			prob = 254
		},
		{
			param2 = 0,
			name = "air",
			prob = 254
		},
		{
			param2 = 0,
			name = "air",
			prob = 254
		},
		{
			param2 = 0,
			name = "air",
			prob = 254
		},
		{
			param2 = 0,
			name = "air",
			prob = 254
		},
		{
			param2 = 0,
			name = "air",
			prob = 254
		},
		{
			param2 = 0,
			name = "air",
			prob = 254
		},
		{
			param2 = 0,
			name = "air",
			prob = 254
		},
		{
			param2 = 0,
			name = "default:dirt_with_grass",
			prob = 254
		},
		{
			param2 = 0,
			name = "default:dirt_with_grass",
			prob = 254
		},
		{
			param2 = 0,
			name = "default:dirt_with_grass",
			prob = 254
		},
		{
			param2 = 0,
			name = "default:dirt_with_grass",
			prob = 254
		},
		{
			param2 = 0,
			name = "default:dirt_with_grass",
			prob = 254
		},
		{
			param2 = 0,
			name = "air",
			prob = 254
		},
		{
			param2 = 4,
			name = "cottages:wagon_wheel",
			prob = 254
		},
		{
			param2 = 0,
			name = "air",
			prob = 254
		},
		{
			param2 = 4,
			name = "cottages:wagon_wheel",
			prob = 254
		},
		{
			param2 = 0,
			name = "air",
			prob = 254
		},
		{
			param2 = 0,
			name = "air",
			prob = 254
		},
		{
			param2 = 0,
			name = "air",
			prob = 254
		},
		{
			param2 = 0,
			name = "cottages:bench",
			prob = 254
		},
		{
			param2 = 0,
			name = "cottages:bench",
			prob = 254
		},
		{
			param2 = 0,
			name = "air",
			prob = 254
		},
		{
			param2 = 0,
			name = "default:dirt_with_grass",
			prob = 254
		},
		{
			param2 = 0,
			name = "default:dirt_with_grass",
			prob = 254
		},
		{
			param2 = 0,
			name = "default:dirt_with_grass",
			prob = 254
		},
		{
			param2 = 0,
			name = "default:dirt_with_grass",
			prob = 254
		},
		{
			param2 = 0,
			name = "default:dirt_with_grass",
			prob = 254
		},
		{
			param2 = 0,
			name = "air",
			prob = 254
		},
		{
			param2 = 23,
			name = "cottages:bench",
			prob = 254
		},
		{
			param2 = 0,
			name = "air",
			prob = 254
		},
		{
			param2 = 21,
			name = "cottages:bench",
			prob = 254
		},
		{
			param2 = 21,
			name = "cottages:bench",
			prob = 254
		},
		{
			param2 = 0,
			name = "air",
			prob = 254
		},
		{
			param2 = 1,
			name = "cottages:bench",
			prob = 254
		},
		{
			param2 = 3,
			name = "cottages:hatch_wood",
			prob = 254
		},
		{
			param2 = 3,
			name = "cottages:hatch_wood",
			prob = 254
		},
		{
			param2 = 0,
			name = "air",
			prob = 254
		},
		{
			param2 = 0,
			name = "default:dirt_with_grass",
			prob = 254
		},
		{
			param2 = 0,
			name = "default:dirt_with_grass",
			prob = 254
		},
		{
			param2 = 0,
			name = "default:dirt_with_grass",
			prob = 254
		},
		{
			param2 = 0,
			name = "default:dirt_with_grass",
			prob = 254
		},
		{
			param2 = 0,
			name = "default:dirt_with_grass",
			prob = 254
		},
		{
			param2 = 0,
			name = "air",
			prob = 254
		},
		{
			param2 = 5,
			name = "cottages:wagon_wheel",
			prob = 254
		},
		{
			param2 = 0,
			name = "air",
			prob = 254
		},
		{
			param2 = 5,
			name = "cottages:wagon_wheel",
			prob = 254
		},
		{
			param2 = 0,
			name = "air",
			prob = 254
		},
		{
			param2 = 0,
			name = "air",
			prob = 254
		},
		{
			param2 = 0,
			name = "air",
			prob = 254
		},
		{
			param2 = 2,
			name = "cottages:bench",
			prob = 254
		},
		{
			param2 = 2,
			name = "cottages:bench",
			prob = 254
		},
		{
			param2 = 0,
			name = "air",
			prob = 254
		},
		{
			param2 = 0,
			name = "default:dirt_with_grass",
			prob = 254
		},
		{
			param2 = 0,
			name = "default:dirt_with_grass",
			prob = 254
		},
		{
			param2 = 0,
			name = "default:dirt_with_grass",
			prob = 254
		},
		{
			param2 = 0,
			name = "default:dirt_with_grass",
			prob = 254
		},
		{
			param2 = 0,
			name = "default:dirt_with_grass",
			prob = 254
		},
		{
			param2 = 0,
			name = "air",
			prob = 254
		},
		{
			param2 = 0,
			name = "air",
			prob = 254
		},
		{
			param2 = 0,
			name = "air",
			prob = 254
		},
		{
			param2 = 0,
			name = "air",
			prob = 254
		},
		{
			param2 = 0,
			name = "air",
			prob = 254
		},
		{
			param2 = 0,
			name = "air",
			prob = 254
		},
		{
			param2 = 0,
			name = "air",
			prob = 254
		},
		{
			param2 = 0,
			name = "air",
			prob = 254
		},
		{
			param2 = 0,
			name = "air",
			prob = 254
		},
		{
			param2 = 0,
			name = "air",
			prob = 254
		}
	}
}
lib_towns.schematics["schem_bldg_cottages_wagon_4_x5_y3_z5_r000"] = le_temp_schem

--Wagon 5 Schematic
	le_temp_schem = {
	size = {x = 5,y = 3,z = 5},
	yslice_prob = {
		{
			ypos = 0,
			prob = 254
		},
		{
			ypos = 1,
			prob = 254
		},
		{
			ypos = 2,
			prob = 254
		}
	},
	data = {
		{
			param2 = 0,
			name = "default:dirt_with_grass",
			prob = 254
		},
		{
			param2 = 0,
			name = "default:dirt_with_grass",
			prob = 254
		},
		{
			param2 = 0,
			name = "default:dirt_with_grass",
			prob = 254
		},
		{
			param2 = 0,
			name = "default:dirt_with_grass",
			prob = 254
		},
		{
			param2 = 0,
			name = "default:dirt_with_grass",
			prob = 254
		},
		{
			param2 = 0,
			name = "air",
			prob = 254
		},
		{
			param2 = 0,
			name = "air",
			prob = 254
		},
		{
			param2 = 0,
			name = "air",
			prob = 254
		},
		{
			param2 = 0,
			name = "air",
			prob = 254
		},
		{
			param2 = 0,
			name = "air",
			prob = 254
		},
		{
			param2 = 0,
			name = "air",
			prob = 254
		},
		{
			param2 = 0,
			name = "air",
			prob = 254
		},
		{
			param2 = 0,
			name = "air",
			prob = 254
		},
		{
			param2 = 0,
			name = "air",
			prob = 254
		},
		{
			param2 = 0,
			name = "air",
			prob = 254
		},
		{
			param2 = 0,
			name = "default:dirt_with_grass",
			prob = 254
		},
		{
			param2 = 0,
			name = "default:dirt_with_grass",
			prob = 254
		},
		{
			param2 = 0,
			name = "default:dirt_with_grass",
			prob = 254
		},
		{
			param2 = 0,
			name = "default:dirt_with_grass",
			prob = 254
		},
		{
			param2 = 0,
			name = "default:dirt_with_grass",
			prob = 254
		},
		{
			param2 = 0,
			name = "air",
			prob = 254
		},
		{
			param2 = 4,
			name = "cottages:wagon_wheel",
			prob = 254
		},
		{
			param2 = 0,
			name = "air",
			prob = 254
		},
		{
			param2 = 4,
			name = "cottages:wagon_wheel",
			prob = 254
		},
		{
			param2 = 0,
			name = "air",
			prob = 254
		},
		{
			param2 = 0,
			name = "air",
			prob = 254
		},
		{
			param2 = 0,
			name = "air",
			prob = 254
		},
		{
			param2 = 0,
			name = "cottages:bench",
			prob = 254
		},
		{
			param2 = 0,
			name = "cottages:bench",
			prob = 254
		},
		{
			param2 = 0,
			name = "air",
			prob = 254
		},
		{
			param2 = 0,
			name = "default:dirt_with_grass",
			prob = 254
		},
		{
			param2 = 0,
			name = "default:dirt_with_grass",
			prob = 254
		},
		{
			param2 = 0,
			name = "default:dirt_with_grass",
			prob = 254
		},
		{
			param2 = 0,
			name = "default:dirt_with_grass",
			prob = 254
		},
		{
			param2 = 0,
			name = "default:dirt_with_grass",
			prob = 254
		},
		{
			param2 = 0,
			name = "air",
			prob = 254
		},
		{
			param2 = 23,
			name = "cottages:bench",
			prob = 254
		},
		{
			param2 = 21,
			name = "cottages:hatch_wood",
			prob = 254
		},
		{
			param2 = 21,
			name = "cottages:bench",
			prob = 254
		},
		{
			param2 = 21,
			name = "cottages:bench",
			prob = 254
		},
		{
			param2 = 0,
			name = "air",
			prob = 254
		},
		{
			param2 = 1,
			name = "cottages:bench",
			prob = 254
		},
		{
			param2 = 3,
			name = "cottages:fence_small",
			prob = 254
		},
		{
			param2 = 3,
			name = "cottages:hatch_wood",
			prob = 254
		},
		{
			param2 = 0,
			name = "air",
			prob = 254
		},
		{
			param2 = 0,
			name = "default:dirt_with_grass",
			prob = 254
		},
		{
			param2 = 0,
			name = "default:dirt_with_grass",
			prob = 254
		},
		{
			param2 = 0,
			name = "default:dirt_with_grass",
			prob = 254
		},
		{
			param2 = 0,
			name = "default:dirt_with_grass",
			prob = 254
		},
		{
			param2 = 0,
			name = "default:dirt_with_grass",
			prob = 254
		},
		{
			param2 = 0,
			name = "air",
			prob = 254
		},
		{
			param2 = 5,
			name = "cottages:wagon_wheel",
			prob = 254
		},
		{
			param2 = 0,
			name = "air",
			prob = 254
		},
		{
			param2 = 5,
			name = "cottages:wagon_wheel",
			prob = 254
		},
		{
			param2 = 0,
			name = "air",
			prob = 254
		},
		{
			param2 = 0,
			name = "air",
			prob = 254
		},
		{
			param2 = 0,
			name = "air",
			prob = 254
		},
		{
			param2 = 2,
			name = "cottages:bench",
			prob = 254
		},
		{
			param2 = 2,
			name = "cottages:bench",
			prob = 254
		},
		{
			param2 = 0,
			name = "air",
			prob = 254
		},
		{
			param2 = 0,
			name = "default:dirt_with_grass",
			prob = 254
		},
		{
			param2 = 0,
			name = "default:dirt_with_grass",
			prob = 254
		},
		{
			param2 = 0,
			name = "default:dirt_with_grass",
			prob = 254
		},
		{
			param2 = 0,
			name = "default:dirt_with_grass",
			prob = 254
		},
		{
			param2 = 0,
			name = "default:dirt_with_grass",
			prob = 254
		},
		{
			param2 = 0,
			name = "air",
			prob = 254
		},
		{
			param2 = 0,
			name = "air",
			prob = 254
		},
		{
			param2 = 0,
			name = "air",
			prob = 254
		},
		{
			param2 = 0,
			name = "air",
			prob = 254
		},
		{
			param2 = 0,
			name = "air",
			prob = 254
		},
		{
			param2 = 0,
			name = "air",
			prob = 254
		},
		{
			param2 = 0,
			name = "air",
			prob = 254
		},
		{
			param2 = 0,
			name = "air",
			prob = 254
		},
		{
			param2 = 0,
			name = "air",
			prob = 254
		},
		{
			param2 = 0,
			name = "air",
			prob = 254
		}
	}
}
lib_towns.schematics["schem_bldg_cottages_wagon_5_x5_y3_z5_r000"] = le_temp_schem

--Wagon 6 Schematic
	le_temp_schem = {
	size = {x = 5,y = 3,z = 5},
	yslice_prob = {
		{
			ypos = 0,
			prob = 254
		},
		{
			ypos = 1,
			prob = 254
		},
		{
			ypos = 2,
			prob = 254
		}
	},
	data = {
		{
			param2 = 0,
			name = "default:dirt_with_grass",
			prob = 254
		},
		{
			param2 = 0,
			name = "default:dirt_with_grass",
			prob = 254
		},
		{
			param2 = 0,
			name = "default:dirt_with_grass",
			prob = 254
		},
		{
			param2 = 0,
			name = "default:dirt_with_grass",
			prob = 254
		},
		{
			param2 = 0,
			name = "default:dirt_with_grass",
			prob = 254
		},
		{
			param2 = 0,
			name = "air",
			prob = 254
		},
		{
			param2 = 0,
			name = "air",
			prob = 254
		},
		{
			param2 = 0,
			name = "air",
			prob = 254
		},
		{
			param2 = 0,
			name = "air",
			prob = 254
		},
		{
			param2 = 0,
			name = "air",
			prob = 254
		},
		{
			param2 = 0,
			name = "air",
			prob = 254
		},
		{
			param2 = 0,
			name = "air",
			prob = 254
		},
		{
			param2 = 0,
			name = "air",
			prob = 254
		},
		{
			param2 = 0,
			name = "air",
			prob = 254
		},
		{
			param2 = 0,
			name = "air",
			prob = 254
		},
		{
			param2 = 0,
			name = "default:dirt_with_grass",
			prob = 254
		},
		{
			param2 = 0,
			name = "default:dirt_with_grass",
			prob = 254
		},
		{
			param2 = 0,
			name = "default:dirt_with_grass",
			prob = 254
		},
		{
			param2 = 0,
			name = "default:dirt_with_grass",
			prob = 254
		},
		{
			param2 = 0,
			name = "default:dirt_with_grass",
			prob = 254
		},
		{
			param2 = 0,
			name = "air",
			prob = 254
		},
		{
			param2 = 4,
			name = "cottages:wagon_wheel",
			prob = 254
		},
		{
			param2 = 0,
			name = "air",
			prob = 254
		},
		{
			param2 = 4,
			name = "cottages:wagon_wheel",
			prob = 254
		},
		{
			param2 = 0,
			name = "air",
			prob = 254
		},
		{
			param2 = 0,
			name = "air",
			prob = 254
		},
		{
			param2 = 0,
			name = "air",
			prob = 254
		},
		{
			param2 = 0,
			name = "air",
			prob = 254
		},
		{
			param2 = 0,
			name = "air",
			prob = 254
		},
		{
			param2 = 0,
			name = "air",
			prob = 254
		},
		{
			param2 = 0,
			name = "default:dirt_with_grass",
			prob = 254
		},
		{
			param2 = 0,
			name = "default:dirt_with_grass",
			prob = 254
		},
		{
			param2 = 0,
			name = "default:dirt_with_grass",
			prob = 254
		},
		{
			param2 = 0,
			name = "default:dirt_with_grass",
			prob = 254
		},
		{
			param2 = 0,
			name = "default:dirt_with_grass",
			prob = 254
		},
		{
			param2 = 0,
			name = "air",
			prob = 254
		},
		{
			param2 = 23,
			name = "cottages:bench",
			prob = 254
		},
		{
			param2 = 0,
			name = "air",
			prob = 254
		},
		{
			param2 = 21,
			name = "cottages:bench",
			prob = 254
		},
		{
			param2 = 21,
			name = "cottages:bench",
			prob = 254
		},
		{
			param2 = 0,
			name = "air",
			prob = 254
		},
		{
			param2 = 1,
			name = "cottages:bench",
			prob = 254
		},
		{
			param2 = 3,
			name = "cottages:hatch_wood",
			prob = 254
		},
		{
			param2 = 3,
			name = "cottages:hatch_wood",
			prob = 254
		},
		{
			param2 = 0,
			name = "air",
			prob = 254
		},
		{
			param2 = 0,
			name = "default:dirt_with_grass",
			prob = 254
		},
		{
			param2 = 0,
			name = "default:dirt_with_grass",
			prob = 254
		},
		{
			param2 = 0,
			name = "default:dirt_with_grass",
			prob = 254
		},
		{
			param2 = 0,
			name = "default:dirt_with_grass",
			prob = 254
		},
		{
			param2 = 0,
			name = "default:dirt_with_grass",
			prob = 254
		},
		{
			param2 = 0,
			name = "air",
			prob = 254
		},
		{
			param2 = 5,
			name = "cottages:wagon_wheel",
			prob = 254
		},
		{
			param2 = 0,
			name = "air",
			prob = 254
		},
		{
			param2 = 5,
			name = "cottages:wagon_wheel",
			prob = 254
		},
		{
			param2 = 0,
			name = "air",
			prob = 254
		},
		{
			param2 = 0,
			name = "air",
			prob = 254
		},
		{
			param2 = 0,
			name = "air",
			prob = 254
		},
		{
			param2 = 0,
			name = "air",
			prob = 254
		},
		{
			param2 = 0,
			name = "air",
			prob = 254
		},
		{
			param2 = 0,
			name = "air",
			prob = 254
		},
		{
			param2 = 0,
			name = "default:dirt_with_grass",
			prob = 254
		},
		{
			param2 = 0,
			name = "default:dirt_with_grass",
			prob = 254
		},
		{
			param2 = 0,
			name = "default:dirt_with_grass",
			prob = 254
		},
		{
			param2 = 0,
			name = "default:dirt_with_grass",
			prob = 254
		},
		{
			param2 = 0,
			name = "default:dirt_with_grass",
			prob = 254
		},
		{
			param2 = 0,
			name = "air",
			prob = 254
		},
		{
			param2 = 0,
			name = "air",
			prob = 254
		},
		{
			param2 = 0,
			name = "air",
			prob = 254
		},
		{
			param2 = 0,
			name = "air",
			prob = 254
		},
		{
			param2 = 0,
			name = "air",
			prob = 254
		},
		{
			param2 = 0,
			name = "air",
			prob = 254
		},
		{
			param2 = 0,
			name = "air",
			prob = 254
		},
		{
			param2 = 0,
			name = "air",
			prob = 254
		},
		{
			param2 = 0,
			name = "air",
			prob = 254
		},
		{
			param2 = 0,
			name = "air",
			prob = 254
		}
	}
}
lib_towns.schematics["schem_bldg_cottages_wagon_6_x5_y3_z5_r000"] = le_temp_schem

--Wagon 7 Schematic
	le_temp_schem = {
	size = {x = 5,y = 3,z = 5},
	yslice_prob = {
		{
			ypos = 0,
			prob = 254
		},
		{
			ypos = 1,
			prob = 254
		},
		{
			ypos = 2,
			prob = 254
		}
	},
	data = {
		{
			param2 = 0,
			name = "default:dirt_with_grass",
			prob = 254
		},
		{
			param2 = 0,
			name = "default:dirt_with_grass",
			prob = 254
		},
		{
			param2 = 0,
			name = "default:dirt_with_grass",
			prob = 254
		},
		{
			param2 = 0,
			name = "default:dirt_with_grass",
			prob = 254
		},
		{
			param2 = 0,
			name = "default:dirt_with_grass",
			prob = 254
		},
		{
			param2 = 0,
			name = "air",
			prob = 254
		},
		{
			param2 = 0,
			name = "air",
			prob = 254
		},
		{
			param2 = 0,
			name = "air",
			prob = 254
		},
		{
			param2 = 0,
			name = "air",
			prob = 254
		},
		{
			param2 = 0,
			name = "air",
			prob = 254
		},
		{
			param2 = 0,
			name = "air",
			prob = 254
		},
		{
			param2 = 0,
			name = "air",
			prob = 254
		},
		{
			param2 = 0,
			name = "air",
			prob = 254
		},
		{
			param2 = 0,
			name = "air",
			prob = 254
		},
		{
			param2 = 0,
			name = "air",
			prob = 254
		},
		{
			param2 = 0,
			name = "default:dirt_with_grass",
			prob = 254
		},
		{
			param2 = 0,
			name = "default:dirt_with_grass",
			prob = 254
		},
		{
			param2 = 0,
			name = "default:dirt_with_grass",
			prob = 254
		},
		{
			param2 = 0,
			name = "default:dirt_with_grass",
			prob = 254
		},
		{
			param2 = 0,
			name = "default:dirt_with_grass",
			prob = 254
		},
		{
			param2 = 0,
			name = "air",
			prob = 254
		},
		{
			param2 = 4,
			name = "cottages:wagon_wheel",
			prob = 254
		},
		{
			param2 = 0,
			name = "air",
			prob = 254
		},
		{
			param2 = 4,
			name = "cottages:wagon_wheel",
			prob = 254
		},
		{
			param2 = 0,
			name = "air",
			prob = 254
		},
		{
			param2 = 0,
			name = "air",
			prob = 254
		},
		{
			param2 = 0,
			name = "air",
			prob = 254
		},
		{
			param2 = 0,
			name = "cottages:bench",
			prob = 254
		},
		{
			param2 = 0,
			name = "cottages:bench",
			prob = 254
		},
		{
			param2 = 0,
			name = "air",
			prob = 254
		},
		{
			param2 = 0,
			name = "default:dirt_with_grass",
			prob = 254
		},
		{
			param2 = 0,
			name = "default:dirt_with_grass",
			prob = 254
		},
		{
			param2 = 0,
			name = "default:dirt_with_grass",
			prob = 254
		},
		{
			param2 = 0,
			name = "default:dirt_with_grass",
			prob = 254
		},
		{
			param2 = 0,
			name = "default:dirt_with_grass",
			prob = 254
		},
		{
			param2 = 0,
			name = "air",
			prob = 254
		},
		{
			param2 = 23,
			name = "cottages:bench",
			prob = 254
		},
		{
			param2 = 0,
			name = "air",
			prob = 254
		},
		{
			param2 = 21,
			name = "cottages:bench",
			prob = 254
		},
		{
			param2 = 21,
			name = "cottages:bench",
			prob = 254
		},
		{
			param2 = 0,
			name = "air",
			prob = 254
		},
		{
			param2 = 1,
			name = "cottages:bench",
			prob = 254
		},
		{
			param2 = 3,
			name = "cottages:sleeping_mat",
			prob = 254
		},
		{
			param2 = 0,
			name = "cottages:sleeping_mat",
			prob = 254
		},
		{
			param2 = 0,
			name = "air",
			prob = 254
		},
		{
			param2 = 0,
			name = "default:dirt_with_grass",
			prob = 254
		},
		{
			param2 = 0,
			name = "default:dirt_with_grass",
			prob = 254
		},
		{
			param2 = 0,
			name = "default:dirt_with_grass",
			prob = 254
		},
		{
			param2 = 0,
			name = "default:dirt_with_grass",
			prob = 254
		},
		{
			param2 = 0,
			name = "default:dirt_with_grass",
			prob = 254
		},
		{
			param2 = 0,
			name = "air",
			prob = 254
		},
		{
			param2 = 5,
			name = "cottages:wagon_wheel",
			prob = 254
		},
		{
			param2 = 0,
			name = "air",
			prob = 254
		},
		{
			param2 = 5,
			name = "cottages:wagon_wheel",
			prob = 254
		},
		{
			param2 = 0,
			name = "air",
			prob = 254
		},
		{
			param2 = 0,
			name = "air",
			prob = 254
		},
		{
			param2 = 0,
			name = "air",
			prob = 254
		},
		{
			param2 = 2,
			name = "cottages:bench",
			prob = 254
		},
		{
			param2 = 2,
			name = "cottages:bench",
			prob = 254
		},
		{
			param2 = 0,
			name = "air",
			prob = 254
		},
		{
			param2 = 0,
			name = "default:dirt_with_grass",
			prob = 254
		},
		{
			param2 = 0,
			name = "default:dirt_with_grass",
			prob = 254
		},
		{
			param2 = 0,
			name = "default:dirt_with_grass",
			prob = 254
		},
		{
			param2 = 0,
			name = "default:dirt_with_grass",
			prob = 254
		},
		{
			param2 = 0,
			name = "default:dirt_with_grass",
			prob = 254
		},
		{
			param2 = 0,
			name = "air",
			prob = 254
		},
		{
			param2 = 0,
			name = "air",
			prob = 254
		},
		{
			param2 = 0,
			name = "air",
			prob = 254
		},
		{
			param2 = 0,
			name = "air",
			prob = 254
		},
		{
			param2 = 0,
			name = "air",
			prob = 254
		},
		{
			param2 = 0,
			name = "air",
			prob = 254
		},
		{
			param2 = 0,
			name = "air",
			prob = 254
		},
		{
			param2 = 0,
			name = "air",
			prob = 254
		},
		{
			param2 = 0,
			name = "air",
			prob = 254
		},
		{
			param2 = 0,
			name = "air",
			prob = 254
		}
	}
}
lib_towns.schematics["schem_bldg_cottages_wagon_7_x5_y3_z5_r000"] = le_temp_schem

--Wagon 8 Schematic
	le_temp_schem = {
	size = {x = 5,y = 5,z = 5},
	yslice_prob = {
		{
			ypos = 0,
			prob = 254
		},
		{
			ypos = 1,
			prob = 254
		},
		{
			ypos = 2,
			prob = 254
		},
		{
			ypos = 3,
			prob = 254
		},
		{
			ypos = 4,
			prob = 254
		}
	},
	data = {
		{
			param2 = 0,
			name = "default:dirt_with_grass",
			prob = 254
		},
		{
			param2 = 0,
			name = "default:dirt_with_grass",
			prob = 254
		},
		{
			param2 = 0,
			name = "default:dirt_with_grass",
			prob = 254
		},
		{
			param2 = 0,
			name = "default:dirt_with_grass",
			prob = 254
		},
		{
			param2 = 0,
			name = "default:dirt_with_grass",
			prob = 254
		},
		{
			param2 = 0,
			name = "air",
			prob = 254
		},
		{
			param2 = 0,
			name = "air",
			prob = 254
		},
		{
			param2 = 0,
			name = "air",
			prob = 254
		},
		{
			param2 = 0,
			name = "air",
			prob = 254
		},
		{
			param2 = 0,
			name = "air",
			prob = 254
		},
		{
			param2 = 0,
			name = "air",
			prob = 254
		},
		{
			param2 = 0,
			name = "air",
			prob = 254
		},
		{
			param2 = 0,
			name = "air",
			prob = 254
		},
		{
			param2 = 0,
			name = "air",
			prob = 254
		},
		{
			param2 = 0,
			name = "air",
			prob = 254
		},
		{
			param2 = 0,
			name = "air",
			prob = 254
		},
		{
			param2 = 0,
			name = "air",
			prob = 254
		},
		{
			param2 = 0,
			name = "air",
			prob = 254
		},
		{
			param2 = 0,
			name = "air",
			prob = 254
		},
		{
			param2 = 0,
			name = "air",
			prob = 254
		},
		{
			param2 = 0,
			name = "air",
			prob = 254
		},
		{
			param2 = 0,
			name = "air",
			prob = 254
		},
		{
			param2 = 0,
			name = "air",
			prob = 254
		},
		{
			param2 = 0,
			name = "air",
			prob = 254
		},
		{
			param2 = 0,
			name = "air",
			prob = 254
		},
		{
			param2 = 0,
			name = "default:dirt_with_grass",
			prob = 254
		},
		{
			param2 = 0,
			name = "default:dirt_with_grass",
			prob = 254
		},
		{
			param2 = 0,
			name = "default:dirt_with_grass",
			prob = 254
		},
		{
			param2 = 0,
			name = "default:dirt_with_grass",
			prob = 254
		},
		{
			param2 = 0,
			name = "default:dirt_with_grass",
			prob = 254
		},
		{
			param2 = 0,
			name = "air",
			prob = 254
		},
		{
			param2 = 4,
			name = "cottages:wagon_wheel",
			prob = 254
		},
		{
			param2 = 0,
			name = "air",
			prob = 254
		},
		{
			param2 = 4,
			name = "cottages:wagon_wheel",
			prob = 254
		},
		{
			param2 = 0,
			name = "air",
			prob = 254
		},
		{
			param2 = 0,
			name = "air",
			prob = 254
		},
		{
			param2 = 0,
			name = "air",
			prob = 254
		},
		{
			param2 = 8,
			name = "cottages:sleeping_mat",
			prob = 254
		},
		{
			param2 = 8,
			name = "cottages:sleeping_mat",
			prob = 254
		},
		{
			param2 = 0,
			name = "air",
			prob = 254
		},
		{
			param2 = 0,
			name = "air",
			prob = 254
		},
		{
			param2 = 0,
			name = "air",
			prob = 254
		},
		{
			param2 = 8,
			name = "cottages:sleeping_mat",
			prob = 254
		},
		{
			param2 = 8,
			name = "cottages:sleeping_mat",
			prob = 254
		},
		{
			param2 = 0,
			name = "air",
			prob = 254
		},
		{
			param2 = 0,
			name = "air",
			prob = 254
		},
		{
			param2 = 0,
			name = "air",
			prob = 254
		},
		{
			param2 = 0,
			name = "air",
			prob = 254
		},
		{
			param2 = 0,
			name = "air",
			prob = 254
		},
		{
			param2 = 0,
			name = "air",
			prob = 254
		},
		{
			param2 = 0,
			name = "default:dirt_with_grass",
			prob = 254
		},
		{
			param2 = 0,
			name = "default:dirt_with_grass",
			prob = 254
		},
		{
			param2 = 0,
			name = "default:dirt_with_grass",
			prob = 254
		},
		{
			param2 = 0,
			name = "default:dirt_with_grass",
			prob = 254
		},
		{
			param2 = 0,
			name = "default:dirt_with_grass",
			prob = 254
		},
		{
			param2 = 0,
			name = "air",
			prob = 254
		},
		{
			param2 = 23,
			name = "cottages:bench",
			prob = 254
		},
		{
			param2 = 0,
			name = "air",
			prob = 254
		},
		{
			param2 = 21,
			name = "cottages:bench",
			prob = 254
		},
		{
			param2 = 21,
			name = "cottages:bench",
			prob = 254
		},
		{
			param2 = 0,
			name = "air",
			prob = 254
		},
		{
			param2 = 1,
			name = "cottages:bench",
			prob = 254
		},
		{
			param2 = 3,
			name = "cottages:hatch_wood",
			prob = 254
		},
		{
			param2 = 3,
			name = "cottages:hatch_wood",
			prob = 254
		},
		{
			param2 = 12,
			name = "cottages:sleeping_mat",
			prob = 254
		},
		{
			param2 = 0,
			name = "air",
			prob = 254
		},
		{
			param2 = 16,
			name = "cottages:sleeping_mat",
			prob = 254
		},
		{
			param2 = 0,
			name = "air",
			prob = 254
		},
		{
			param2 = 0,
			name = "air",
			prob = 254
		},
		{
			param2 = 12,
			name = "cottages:sleeping_mat",
			prob = 254
		},
		{
			param2 = 0,
			name = "air",
			prob = 254
		},
		{
			param2 = 0,
			name = "air",
			prob = 254
		},
		{
			param2 = 3,
			name = "cottages:sleeping_mat",
			prob = 254
		},
		{
			param2 = 3,
			name = "cottages:sleeping_mat",
			prob = 254
		},
		{
			param2 = 0,
			name = "air",
			prob = 254
		},
		{
			param2 = 0,
			name = "default:dirt_with_grass",
			prob = 254
		},
		{
			param2 = 0,
			name = "default:dirt_with_grass",
			prob = 254
		},
		{
			param2 = 0,
			name = "default:dirt_with_grass",
			prob = 254
		},
		{
			param2 = 0,
			name = "default:dirt_with_grass",
			prob = 254
		},
		{
			param2 = 0,
			name = "default:dirt_with_grass",
			prob = 254
		},
		{
			param2 = 0,
			name = "air",
			prob = 254
		},
		{
			param2 = 5,
			name = "cottages:wagon_wheel",
			prob = 254
		},
		{
			param2 = 0,
			name = "air",
			prob = 254
		},
		{
			param2 = 5,
			name = "cottages:wagon_wheel",
			prob = 254
		},
		{
			param2 = 0,
			name = "air",
			prob = 254
		},
		{
			param2 = 0,
			name = "air",
			prob = 254
		},
		{
			param2 = 0,
			name = "air",
			prob = 254
		},
		{
			param2 = 4,
			name = "cottages:sleeping_mat",
			prob = 254
		},
		{
			param2 = 4,
			name = "cottages:sleeping_mat",
			prob = 254
		},
		{
			param2 = 0,
			name = "air",
			prob = 254
		},
		{
			param2 = 0,
			name = "air",
			prob = 254
		},
		{
			param2 = 0,
			name = "air",
			prob = 254
		},
		{
			param2 = 4,
			name = "cottages:sleeping_mat",
			prob = 254
		},
		{
			param2 = 4,
			name = "cottages:sleeping_mat",
			prob = 254
		},
		{
			param2 = 0,
			name = "air",
			prob = 254
		},
		{
			param2 = 0,
			name = "air",
			prob = 254
		},
		{
			param2 = 0,
			name = "air",
			prob = 254
		},
		{
			param2 = 0,
			name = "air",
			prob = 254
		},
		{
			param2 = 0,
			name = "air",
			prob = 254
		},
		{
			param2 = 0,
			name = "air",
			prob = 254
		},
		{
			param2 = 0,
			name = "default:dirt_with_grass",
			prob = 254
		},
		{
			param2 = 0,
			name = "default:dirt_with_grass",
			prob = 254
		},
		{
			param2 = 0,
			name = "default:dirt_with_grass",
			prob = 254
		},
		{
			param2 = 0,
			name = "default:dirt_with_grass",
			prob = 254
		},
		{
			param2 = 0,
			name = "default:dirt_with_grass",
			prob = 254
		},
		{
			param2 = 0,
			name = "air",
			prob = 254
		},
		{
			param2 = 0,
			name = "air",
			prob = 254
		},
		{
			param2 = 0,
			name = "air",
			prob = 254
		},
		{
			param2 = 0,
			name = "air",
			prob = 254
		},
		{
			param2 = 0,
			name = "air",
			prob = 254
		},
		{
			param2 = 0,
			name = "air",
			prob = 254
		},
		{
			param2 = 0,
			name = "air",
			prob = 254
		},
		{
			param2 = 0,
			name = "air",
			prob = 254
		},
		{
			param2 = 0,
			name = "air",
			prob = 254
		},
		{
			param2 = 0,
			name = "air",
			prob = 254
		},
		{
			param2 = 0,
			name = "air",
			prob = 254
		},
		{
			param2 = 0,
			name = "air",
			prob = 254
		},
		{
			param2 = 0,
			name = "air",
			prob = 254
		},
		{
			param2 = 0,
			name = "air",
			prob = 254
		},
		{
			param2 = 0,
			name = "air",
			prob = 254
		},
		{
			param2 = 0,
			name = "air",
			prob = 254
		},
		{
			param2 = 0,
			name = "air",
			prob = 254
		},
		{
			param2 = 0,
			name = "air",
			prob = 254
		},
		{
			param2 = 0,
			name = "air",
			prob = 254
		},
		{
			param2 = 0,
			name = "air",
			prob = 254
		}
	}
}
lib_towns.schematics["schem_bldg_cottages_wagon_8_x5_y5_z5_r000"] = le_temp_schem

--Wagon 9 Schematic
	le_temp_schem = {
	size = {x = 5,y = 3,z = 5},
	yslice_prob = {
		{
			ypos = 0,
			prob = 254
		},
		{
			ypos = 1,
			prob = 254
		},
		{
			ypos = 2,
			prob = 254
		}
	},
	data = {
		{
			param2 = 0,
			name = "default:dirt_with_grass",
			prob = 254
		},
		{
			param2 = 0,
			name = "default:dirt_with_grass",
			prob = 254
		},
		{
			param2 = 0,
			name = "default:dirt_with_grass",
			prob = 254
		},
		{
			param2 = 0,
			name = "default:dirt_with_grass",
			prob = 254
		},
		{
			param2 = 0,
			name = "default:dirt_with_grass",
			prob = 254
		},
		{
			param2 = 0,
			name = "air",
			prob = 254
		},
		{
			param2 = 0,
			name = "air",
			prob = 254
		},
		{
			param2 = 0,
			name = "air",
			prob = 254
		},
		{
			param2 = 0,
			name = "air",
			prob = 254
		},
		{
			param2 = 0,
			name = "air",
			prob = 254
		},
		{
			param2 = 0,
			name = "air",
			prob = 254
		},
		{
			param2 = 0,
			name = "air",
			prob = 254
		},
		{
			param2 = 0,
			name = "air",
			prob = 254
		},
		{
			param2 = 0,
			name = "air",
			prob = 254
		},
		{
			param2 = 0,
			name = "air",
			prob = 254
		},
		{
			param2 = 0,
			name = "default:dirt_with_grass",
			prob = 254
		},
		{
			param2 = 0,
			name = "default:dirt_with_grass",
			prob = 254
		},
		{
			param2 = 0,
			name = "default:dirt_with_grass",
			prob = 254
		},
		{
			param2 = 0,
			name = "default:dirt_with_grass",
			prob = 254
		},
		{
			param2 = 0,
			name = "default:dirt_with_grass",
			prob = 254
		},
		{
			param2 = 0,
			name = "air",
			prob = 254
		},
		{
			param2 = 4,
			name = "cottages:wagon_wheel",
			prob = 254
		},
		{
			param2 = 0,
			name = "air",
			prob = 254
		},
		{
			param2 = 4,
			name = "cottages:wagon_wheel",
			prob = 254
		},
		{
			param2 = 0,
			name = "air",
			prob = 254
		},
		{
			param2 = 0,
			name = "air",
			prob = 254
		},
		{
			param2 = 0,
			name = "air",
			prob = 254
		},
		{
			param2 = 0,
			name = "air",
			prob = 254
		},
		{
			param2 = 0,
			name = "air",
			prob = 254
		},
		{
			param2 = 0,
			name = "air",
			prob = 254
		},
		{
			param2 = 0,
			name = "default:dirt_with_grass",
			prob = 254
		},
		{
			param2 = 0,
			name = "default:dirt_with_grass",
			prob = 254
		},
		{
			param2 = 0,
			name = "default:dirt_with_grass",
			prob = 254
		},
		{
			param2 = 0,
			name = "default:dirt_with_grass",
			prob = 254
		},
		{
			param2 = 0,
			name = "default:dirt_with_grass",
			prob = 254
		},
		{
			param2 = 0,
			name = "air",
			prob = 254
		},
		{
			param2 = 23,
			name = "cottages:bench",
			prob = 254
		},
		{
			param2 = 21,
			name = "cottages:hatch_wood",
			prob = 254
		},
		{
			param2 = 21,
			name = "cottages:bench",
			prob = 254
		},
		{
			param2 = 21,
			name = "cottages:bench",
			prob = 254
		},
		{
			param2 = 0,
			name = "air",
			prob = 254
		},
		{
			param2 = 1,
			name = "cottages:bench",
			prob = 254
		},
		{
			param2 = 1,
			name = "default:chest",
			prob = 254
		},
		{
			param2 = 3,
			name = "default:chest",
			prob = 254
		},
		{
			param2 = 0,
			name = "air",
			prob = 254
		},
		{
			param2 = 0,
			name = "default:dirt_with_grass",
			prob = 254
		},
		{
			param2 = 0,
			name = "default:dirt_with_grass",
			prob = 254
		},
		{
			param2 = 0,
			name = "default:dirt_with_grass",
			prob = 254
		},
		{
			param2 = 0,
			name = "default:dirt_with_grass",
			prob = 254
		},
		{
			param2 = 0,
			name = "default:dirt_with_grass",
			prob = 254
		},
		{
			param2 = 0,
			name = "air",
			prob = 254
		},
		{
			param2 = 5,
			name = "cottages:wagon_wheel",
			prob = 254
		},
		{
			param2 = 0,
			name = "air",
			prob = 254
		},
		{
			param2 = 5,
			name = "cottages:wagon_wheel",
			prob = 254
		},
		{
			param2 = 0,
			name = "air",
			prob = 254
		},
		{
			param2 = 0,
			name = "air",
			prob = 254
		},
		{
			param2 = 0,
			name = "air",
			prob = 254
		},
		{
			param2 = 0,
			name = "air",
			prob = 254
		},
		{
			param2 = 0,
			name = "air",
			prob = 254
		},
		{
			param2 = 0,
			name = "air",
			prob = 254
		},
		{
			param2 = 0,
			name = "default:dirt_with_grass",
			prob = 254
		},
		{
			param2 = 0,
			name = "default:dirt_with_grass",
			prob = 254
		},
		{
			param2 = 0,
			name = "default:dirt_with_grass",
			prob = 254
		},
		{
			param2 = 0,
			name = "default:dirt_with_grass",
			prob = 254
		},
		{
			param2 = 0,
			name = "default:dirt_with_grass",
			prob = 254
		},
		{
			param2 = 0,
			name = "air",
			prob = 254
		},
		{
			param2 = 0,
			name = "air",
			prob = 254
		},
		{
			param2 = 0,
			name = "air",
			prob = 254
		},
		{
			param2 = 0,
			name = "air",
			prob = 254
		},
		{
			param2 = 0,
			name = "air",
			prob = 254
		},
		{
			param2 = 0,
			name = "air",
			prob = 254
		},
		{
			param2 = 0,
			name = "air",
			prob = 254
		},
		{
			param2 = 0,
			name = "air",
			prob = 254
		},
		{
			param2 = 0,
			name = "air",
			prob = 254
		},
		{
			param2 = 0,
			name = "air",
			prob = 254
		}
	}
}
lib_towns.schematics["schem_bldg_cottages_wagon_9_x5_y3_z5_r000"] = le_temp_schem

--Wagon 10 Schematic
	le_temp_schem = {
	size = {x = 5,y = 3,z = 5},
	yslice_prob = {
		{
			ypos = 0,
			prob = 254
		},
		{
			ypos = 1,
			prob = 254
		},
		{
			ypos = 2,
			prob = 254
		}
	},
	data = {
		{
			param2 = 0,
			name = "default:dirt_with_grass",
			prob = 254
		},
		{
			param2 = 0,
			name = "default:dirt_with_grass",
			prob = 254
		},
		{
			param2 = 0,
			name = "default:dirt_with_grass",
			prob = 254
		},
		{
			param2 = 0,
			name = "default:dirt_with_grass",
			prob = 254
		},
		{
			param2 = 0,
			name = "default:dirt_with_grass",
			prob = 254
		},
		{
			param2 = 0,
			name = "air",
			prob = 254
		},
		{
			param2 = 0,
			name = "air",
			prob = 254
		},
		{
			param2 = 0,
			name = "air",
			prob = 254
		},
		{
			param2 = 0,
			name = "air",
			prob = 254
		},
		{
			param2 = 0,
			name = "air",
			prob = 254
		},
		{
			param2 = 0,
			name = "air",
			prob = 254
		},
		{
			param2 = 0,
			name = "air",
			prob = 254
		},
		{
			param2 = 0,
			name = "air",
			prob = 254
		},
		{
			param2 = 0,
			name = "air",
			prob = 254
		},
		{
			param2 = 0,
			name = "air",
			prob = 254
		},
		{
			param2 = 0,
			name = "default:dirt_with_grass",
			prob = 254
		},
		{
			param2 = 0,
			name = "default:dirt_with_grass",
			prob = 254
		},
		{
			param2 = 0,
			name = "default:dirt_with_grass",
			prob = 254
		},
		{
			param2 = 0,
			name = "default:dirt_with_grass",
			prob = 254
		},
		{
			param2 = 0,
			name = "default:dirt_with_grass",
			prob = 254
		},
		{
			param2 = 0,
			name = "air",
			prob = 254
		},
		{
			param2 = 4,
			name = "cottages:wagon_wheel",
			prob = 254
		},
		{
			param2 = 0,
			name = "air",
			prob = 254
		},
		{
			param2 = 4,
			name = "cottages:wagon_wheel",
			prob = 254
		},
		{
			param2 = 0,
			name = "air",
			prob = 254
		},
		{
			param2 = 0,
			name = "air",
			prob = 254
		},
		{
			param2 = 0,
			name = "air",
			prob = 254
		},
		{
			param2 = 0,
			name = "cottages:bench",
			prob = 254
		},
		{
			param2 = 0,
			name = "cottages:bench",
			prob = 254
		},
		{
			param2 = 0,
			name = "air",
			prob = 254
		},
		{
			param2 = 0,
			name = "default:dirt_with_grass",
			prob = 254
		},
		{
			param2 = 0,
			name = "default:dirt_with_grass",
			prob = 254
		},
		{
			param2 = 0,
			name = "default:dirt_with_grass",
			prob = 254
		},
		{
			param2 = 0,
			name = "default:dirt_with_grass",
			prob = 254
		},
		{
			param2 = 0,
			name = "default:dirt_with_grass",
			prob = 254
		},
		{
			param2 = 0,
			name = "air",
			prob = 254
		},
		{
			param2 = 23,
			name = "cottages:bench",
			prob = 254
		},
		{
			param2 = 21,
			name = "cottages:hatch_wood",
			prob = 254
		},
		{
			param2 = 21,
			name = "cottages:bench",
			prob = 254
		},
		{
			param2 = 21,
			name = "cottages:bench",
			prob = 254
		},
		{
			param2 = 0,
			name = "air",
			prob = 254
		},
		{
			param2 = 1,
			name = "cottages:bench",
			prob = 254
		},
		{
			param2 = 3,
			name = "cottages:fence_small",
			prob = 254
		},
		{
			param2 = 3,
			name = "cottages:hatch_wood",
			prob = 254
		},
		{
			param2 = 3,
			name = "cottages:half_door",
			prob = 254
		},
		{
			param2 = 0,
			name = "default:dirt_with_grass",
			prob = 254
		},
		{
			param2 = 0,
			name = "default:dirt_with_grass",
			prob = 254
		},
		{
			param2 = 0,
			name = "default:dirt_with_grass",
			prob = 254
		},
		{
			param2 = 0,
			name = "default:dirt_with_grass",
			prob = 254
		},
		{
			param2 = 0,
			name = "default:dirt_with_grass",
			prob = 254
		},
		{
			param2 = 0,
			name = "air",
			prob = 254
		},
		{
			param2 = 5,
			name = "cottages:wagon_wheel",
			prob = 254
		},
		{
			param2 = 0,
			name = "air",
			prob = 254
		},
		{
			param2 = 5,
			name = "cottages:wagon_wheel",
			prob = 254
		},
		{
			param2 = 0,
			name = "air",
			prob = 254
		},
		{
			param2 = 0,
			name = "air",
			prob = 254
		},
		{
			param2 = 0,
			name = "air",
			prob = 254
		},
		{
			param2 = 2,
			name = "cottages:bench",
			prob = 254
		},
		{
			param2 = 2,
			name = "cottages:bench",
			prob = 254
		},
		{
			param2 = 0,
			name = "air",
			prob = 254
		},
		{
			param2 = 0,
			name = "default:dirt_with_grass",
			prob = 254
		},
		{
			param2 = 0,
			name = "default:dirt_with_grass",
			prob = 254
		},
		{
			param2 = 0,
			name = "default:dirt_with_grass",
			prob = 254
		},
		{
			param2 = 0,
			name = "default:dirt_with_grass",
			prob = 254
		},
		{
			param2 = 0,
			name = "default:dirt_with_grass",
			prob = 254
		},
		{
			param2 = 0,
			name = "air",
			prob = 254
		},
		{
			param2 = 0,
			name = "air",
			prob = 254
		},
		{
			param2 = 0,
			name = "air",
			prob = 254
		},
		{
			param2 = 0,
			name = "air",
			prob = 254
		},
		{
			param2 = 0,
			name = "air",
			prob = 254
		},
		{
			param2 = 0,
			name = "air",
			prob = 254
		},
		{
			param2 = 0,
			name = "air",
			prob = 254
		},
		{
			param2 = 0,
			name = "air",
			prob = 254
		},
		{
			param2 = 0,
			name = "air",
			prob = 254
		},
		{
			param2 = 0,
			name = "air",
			prob = 254
		}
	}
}
lib_towns.schematics["schem_bldg_cottages_wagon_10_x5_y3_z5_r000"] = le_temp_schem

--Wagon 11 Schematic
	le_temp_schem = {
	size = {x = 6,y = 3,z = 5},
	yslice_prob = {
		{
			ypos = 0,
			prob = 254
		},
		{
			ypos = 1,
			prob = 254
		},
		{
			ypos = 2,
			prob = 254
		}
	},
	data = {
		{
			param2 = 0,
			name = "default:dirt_with_grass",
			prob = 254
		},
		{
			param2 = 0,
			name = "default:dirt_with_grass",
			prob = 254
		},
		{
			param2 = 0,
			name = "default:dirt_with_grass",
			prob = 254
		},
		{
			param2 = 0,
			name = "default:dirt_with_grass",
			prob = 254
		},
		{
			param2 = 0,
			name = "default:dirt_with_grass",
			prob = 254
		},
		{
			param2 = 0,
			name = "default:dirt_with_grass",
			prob = 254
		},
		{
			param2 = 0,
			name = "air",
			prob = 254
		},
		{
			param2 = 0,
			name = "air",
			prob = 254
		},
		{
			param2 = 0,
			name = "air",
			prob = 254
		},
		{
			param2 = 0,
			name = "air",
			prob = 254
		},
		{
			param2 = 0,
			name = "air",
			prob = 254
		},
		{
			param2 = 0,
			name = "air",
			prob = 254
		},
		{
			param2 = 0,
			name = "air",
			prob = 254
		},
		{
			param2 = 0,
			name = "air",
			prob = 254
		},
		{
			param2 = 0,
			name = "air",
			prob = 254
		},
		{
			param2 = 0,
			name = "air",
			prob = 254
		},
		{
			param2 = 0,
			name = "air",
			prob = 254
		},
		{
			param2 = 0,
			name = "air",
			prob = 254
		},
		{
			param2 = 0,
			name = "default:dirt_with_grass",
			prob = 254
		},
		{
			param2 = 0,
			name = "default:dirt_with_grass",
			prob = 254
		},
		{
			param2 = 0,
			name = "default:dirt_with_grass",
			prob = 254
		},
		{
			param2 = 0,
			name = "default:dirt_with_grass",
			prob = 254
		},
		{
			param2 = 0,
			name = "default:dirt_with_grass",
			prob = 254
		},
		{
			param2 = 0,
			name = "default:dirt_with_grass",
			prob = 254
		},
		{
			param2 = 0,
			name = "air",
			prob = 254
		},
		{
			param2 = 4,
			name = "cottages:wagon_wheel",
			prob = 254
		},
		{
			param2 = 0,
			name = "air",
			prob = 254
		},
		{
			param2 = 0,
			name = "air",
			prob = 254
		},
		{
			param2 = 4,
			name = "cottages:wagon_wheel",
			prob = 254
		},
		{
			param2 = 0,
			name = "air",
			prob = 254
		},
		{
			param2 = 0,
			name = "air",
			prob = 254
		},
		{
			param2 = 0,
			name = "air",
			prob = 254
		},
		{
			param2 = 0,
			name = "air",
			prob = 254
		},
		{
			param2 = 0,
			name = "air",
			prob = 254
		},
		{
			param2 = 0,
			name = "air",
			prob = 254
		},
		{
			param2 = 0,
			name = "air",
			prob = 254
		},
		{
			param2 = 0,
			name = "default:dirt_with_grass",
			prob = 254
		},
		{
			param2 = 0,
			name = "default:dirt_with_grass",
			prob = 254
		},
		{
			param2 = 0,
			name = "default:dirt_with_grass",
			prob = 254
		},
		{
			param2 = 0,
			name = "default:dirt_with_grass",
			prob = 254
		},
		{
			param2 = 0,
			name = "default:dirt_with_grass",
			prob = 254
		},
		{
			param2 = 0,
			name = "default:dirt_with_grass",
			prob = 254
		},
		{
			param2 = 0,
			name = "air",
			prob = 254
		},
		{
			param2 = 23,
			name = "cottages:bench",
			prob = 254
		},
		{
			param2 = 21,
			name = "cottages:hatch_wood",
			prob = 254
		},
		{
			param2 = 21,
			name = "cottages:hatch_wood",
			prob = 254
		},
		{
			param2 = 21,
			name = "cottages:bench",
			prob = 254
		},
		{
			param2 = 0,
			name = "air",
			prob = 254
		},
		{
			param2 = 0,
			name = "air",
			prob = 254
		},
		{
			param2 = 1,
			name = "cottages:bench",
			prob = 254
		},
		{
			param2 = 1,
			name = "cottages:barrel_lying",
			prob = 254
		},
		{
			param2 = 3,
			name = "cottages:barrel_lying",
			prob = 254
		},
		{
			param2 = 3,
			name = "default:chest",
			prob = 254
		},
		{
			param2 = 0,
			name = "air",
			prob = 254
		},
		{
			param2 = 0,
			name = "default:dirt_with_grass",
			prob = 254
		},
		{
			param2 = 0,
			name = "default:dirt_with_grass",
			prob = 254
		},
		{
			param2 = 0,
			name = "default:dirt_with_grass",
			prob = 254
		},
		{
			param2 = 0,
			name = "default:dirt_with_grass",
			prob = 254
		},
		{
			param2 = 0,
			name = "default:dirt_with_grass",
			prob = 254
		},
		{
			param2 = 0,
			name = "default:dirt_with_grass",
			prob = 254
		},
		{
			param2 = 0,
			name = "air",
			prob = 254
		},
		{
			param2 = 5,
			name = "cottages:wagon_wheel",
			prob = 254
		},
		{
			param2 = 0,
			name = "air",
			prob = 254
		},
		{
			param2 = 0,
			name = "air",
			prob = 254
		},
		{
			param2 = 5,
			name = "cottages:wagon_wheel",
			prob = 254
		},
		{
			param2 = 0,
			name = "air",
			prob = 254
		},
		{
			param2 = 0,
			name = "air",
			prob = 254
		},
		{
			param2 = 0,
			name = "air",
			prob = 254
		},
		{
			param2 = 0,
			name = "air",
			prob = 254
		},
		{
			param2 = 0,
			name = "air",
			prob = 254
		},
		{
			param2 = 0,
			name = "air",
			prob = 254
		},
		{
			param2 = 0,
			name = "air",
			prob = 254
		},
		{
			param2 = 0,
			name = "default:dirt_with_grass",
			prob = 254
		},
		{
			param2 = 0,
			name = "default:dirt_with_grass",
			prob = 254
		},
		{
			param2 = 0,
			name = "default:dirt_with_grass",
			prob = 254
		},
		{
			param2 = 0,
			name = "default:dirt_with_grass",
			prob = 254
		},
		{
			param2 = 0,
			name = "default:dirt_with_grass",
			prob = 254
		},
		{
			param2 = 0,
			name = "default:dirt_with_grass",
			prob = 254
		},
		{
			param2 = 0,
			name = "air",
			prob = 254
		},
		{
			param2 = 0,
			name = "air",
			prob = 254
		},
		{
			param2 = 0,
			name = "air",
			prob = 254
		},
		{
			param2 = 0,
			name = "air",
			prob = 254
		},
		{
			param2 = 0,
			name = "air",
			prob = 254
		},
		{
			param2 = 0,
			name = "air",
			prob = 254
		},
		{
			param2 = 0,
			name = "air",
			prob = 254
		},
		{
			param2 = 0,
			name = "air",
			prob = 254
		},
		{
			param2 = 0,
			name = "air",
			prob = 254
		},
		{
			param2 = 0,
			name = "air",
			prob = 254
		},
		{
			param2 = 0,
			name = "air",
			prob = 254
		},
		{
			param2 = 0,
			name = "air",
			prob = 254
		}
	}
}
lib_towns.schematics["schem_bldg_cottages_wagon_11_x6_y3_z5_r000"] = le_temp_schem

--Wagon 12 Schematic
	le_temp_schem = {
	size = {x = 6,y = 3,z = 5},
	yslice_prob = {
		{
			ypos = 0,
			prob = 254
		},
		{
			ypos = 1,
			prob = 254
		},
		{
			ypos = 2,
			prob = 254
		}
	},
	data = {
		{
			param2 = 0,
			name = "default:dirt_with_grass",
			prob = 254
		},
		{
			param2 = 0,
			name = "default:dirt_with_grass",
			prob = 254
		},
		{
			param2 = 0,
			name = "default:dirt_with_grass",
			prob = 254
		},
		{
			param2 = 0,
			name = "default:dirt_with_grass",
			prob = 254
		},
		{
			param2 = 0,
			name = "default:dirt_with_grass",
			prob = 254
		},
		{
			param2 = 0,
			name = "default:dirt_with_grass",
			prob = 254
		},
		{
			param2 = 0,
			name = "air",
			prob = 254
		},
		{
			param2 = 0,
			name = "air",
			prob = 254
		},
		{
			param2 = 0,
			name = "air",
			prob = 254
		},
		{
			param2 = 0,
			name = "air",
			prob = 254
		},
		{
			param2 = 0,
			name = "air",
			prob = 254
		},
		{
			param2 = 0,
			name = "air",
			prob = 254
		},
		{
			param2 = 0,
			name = "air",
			prob = 254
		},
		{
			param2 = 0,
			name = "air",
			prob = 254
		},
		{
			param2 = 0,
			name = "air",
			prob = 254
		},
		{
			param2 = 0,
			name = "air",
			prob = 254
		},
		{
			param2 = 0,
			name = "air",
			prob = 254
		},
		{
			param2 = 0,
			name = "air",
			prob = 254
		},
		{
			param2 = 0,
			name = "default:dirt_with_grass",
			prob = 254
		},
		{
			param2 = 0,
			name = "default:dirt_with_grass",
			prob = 254
		},
		{
			param2 = 0,
			name = "default:dirt_with_grass",
			prob = 254
		},
		{
			param2 = 0,
			name = "default:dirt_with_grass",
			prob = 254
		},
		{
			param2 = 0,
			name = "default:dirt_with_grass",
			prob = 254
		},
		{
			param2 = 0,
			name = "default:dirt_with_grass",
			prob = 254
		},
		{
			param2 = 0,
			name = "air",
			prob = 254
		},
		{
			param2 = 4,
			name = "cottages:wagon_wheel",
			prob = 254
		},
		{
			param2 = 0,
			name = "air",
			prob = 254
		},
		{
			param2 = 1,
			name = "cottages:barrel_lying",
			prob = 254
		},
		{
			param2 = 4,
			name = "cottages:wagon_wheel",
			prob = 254
		},
		{
			param2 = 0,
			name = "air",
			prob = 254
		},
		{
			param2 = 0,
			name = "air",
			prob = 254
		},
		{
			param2 = 0,
			name = "air",
			prob = 254
		},
		{
			param2 = 0,
			name = "air",
			prob = 254
		},
		{
			param2 = 0,
			name = "air",
			prob = 254
		},
		{
			param2 = 0,
			name = "air",
			prob = 254
		},
		{
			param2 = 0,
			name = "air",
			prob = 254
		},
		{
			param2 = 0,
			name = "default:dirt_with_grass",
			prob = 254
		},
		{
			param2 = 0,
			name = "default:dirt_with_grass",
			prob = 254
		},
		{
			param2 = 0,
			name = "default:dirt_with_grass",
			prob = 254
		},
		{
			param2 = 0,
			name = "default:dirt_with_grass",
			prob = 254
		},
		{
			param2 = 0,
			name = "default:dirt_with_grass",
			prob = 254
		},
		{
			param2 = 0,
			name = "default:dirt_with_grass",
			prob = 254
		},
		{
			param2 = 0,
			name = "air",
			prob = 254
		},
		{
			param2 = 23,
			name = "cottages:bench",
			prob = 254
		},
		{
			param2 = 21,
			name = "cottages:hatch_wood",
			prob = 254
		},
		{
			param2 = 21,
			name = "cottages:hatch_wood",
			prob = 254
		},
		{
			param2 = 21,
			name = "cottages:bench",
			prob = 254
		},
		{
			param2 = 0,
			name = "air",
			prob = 254
		},
		{
			param2 = 0,
			name = "air",
			prob = 254
		},
		{
			param2 = 1,
			name = "cottages:bench",
			prob = 254
		},
		{
			param2 = 0,
			name = "cottages:barrel",
			prob = 254
		},
		{
			param2 = 0,
			name = "air",
			prob = 254
		},
		{
			param2 = 3,
			name = "default:chest",
			prob = 254
		},
		{
			param2 = 0,
			name = "air",
			prob = 254
		},
		{
			param2 = 0,
			name = "default:dirt_with_grass",
			prob = 254
		},
		{
			param2 = 0,
			name = "default:dirt_with_grass",
			prob = 254
		},
		{
			param2 = 0,
			name = "default:dirt_with_grass",
			prob = 254
		},
		{
			param2 = 0,
			name = "default:dirt_with_grass",
			prob = 254
		},
		{
			param2 = 0,
			name = "default:dirt_with_grass",
			prob = 254
		},
		{
			param2 = 0,
			name = "default:dirt_with_grass",
			prob = 254
		},
		{
			param2 = 0,
			name = "air",
			prob = 254
		},
		{
			param2 = 5,
			name = "cottages:wagon_wheel",
			prob = 254
		},
		{
			param2 = 0,
			name = "air",
			prob = 254
		},
		{
			param2 = 0,
			name = "air",
			prob = 254
		},
		{
			param2 = 5,
			name = "cottages:wagon_wheel",
			prob = 254
		},
		{
			param2 = 0,
			name = "air",
			prob = 254
		},
		{
			param2 = 0,
			name = "air",
			prob = 254
		},
		{
			param2 = 0,
			name = "air",
			prob = 254
		},
		{
			param2 = 0,
			name = "air",
			prob = 254
		},
		{
			param2 = 0,
			name = "air",
			prob = 254
		},
		{
			param2 = 0,
			name = "air",
			prob = 254
		},
		{
			param2 = 0,
			name = "air",
			prob = 254
		},
		{
			param2 = 0,
			name = "default:dirt_with_grass",
			prob = 254
		},
		{
			param2 = 0,
			name = "default:dirt_with_grass",
			prob = 254
		},
		{
			param2 = 0,
			name = "default:dirt_with_grass",
			prob = 254
		},
		{
			param2 = 0,
			name = "default:dirt_with_grass",
			prob = 254
		},
		{
			param2 = 0,
			name = "default:dirt_with_grass",
			prob = 254
		},
		{
			param2 = 0,
			name = "default:dirt_with_grass",
			prob = 254
		},
		{
			param2 = 0,
			name = "air",
			prob = 254
		},
		{
			param2 = 0,
			name = "air",
			prob = 254
		},
		{
			param2 = 0,
			name = "air",
			prob = 254
		},
		{
			param2 = 0,
			name = "air",
			prob = 254
		},
		{
			param2 = 0,
			name = "air",
			prob = 254
		},
		{
			param2 = 0,
			name = "air",
			prob = 254
		},
		{
			param2 = 0,
			name = "air",
			prob = 254
		},
		{
			param2 = 0,
			name = "air",
			prob = 254
		},
		{
			param2 = 0,
			name = "air",
			prob = 254
		},
		{
			param2 = 0,
			name = "air",
			prob = 254
		},
		{
			param2 = 0,
			name = "air",
			prob = 254
		},
		{
			param2 = 0,
			name = "air",
			prob = 254
		}
	}
}
lib_towns.schematics["schem_bldg_cottages_wagon_12_x6_y3_z5_r000"] = le_temp_schem



