{
	yslice_prob = {
		{
			prob = 254,
			ypos = 0
		}
	},
	data = {
		{
			param2 = 0,
			name = "gal:stone_brick",
			prob = 254
		},
		{
			param2 = 0,
			name = "gal:stone_brick",
			prob = 254
		},
		{
			param2 = 0,
			name = "gal:stone_brick",
			prob = 254
		},
		{
			param2 = 0,
			name = "gal:stone_brick",
			prob = 254
		},
		{
			param2 = 0,
			name = "gal:stone_brick",
			prob = 254
		},
		{
			param2 = 0,
			name = "gal:stone_brick",
			prob = 254
		},
		{
			param2 = 0,
			name = "gal:stone_brick",
			prob = 254
		},
		{
			param2 = 0,
			name = "gal:stone_brick",
			prob = 254
		},
		{
			param2 = 0,
			name = "gal:stone_brick",
			prob = 254
		},
		{
			param2 = 0,
			name = "gal:stone_brick",
			prob = 254
		},
		{
			param2 = 0,
			name = "gal:stone_cobble",
			prob = 254
		},
		{
			param2 = 0,
			name = "gal:stone_cobble",
			prob = 254
		},
		{
			param2 = 0,
			name = "gal:stone_cobble",
			prob = 254
		},
		{
			param2 = 0,
			name = "gal:stone_cobble",
			prob = 254
		},
		{
			param2 = 0,
			name = "gal:stone_cobble",
			prob = 254
		},
		{
			param2 = 0,
			name = "gal:stone_cobble",
			prob = 254
		},
		{
			param2 = 0,
			name = "gal:stone_cobble",
			prob = 254
		},
		{
			param2 = 0,
			name = "gal:stone_brick",
			prob = 254
		},
		{
			param2 = 0,
			name = "gal:stone_cobble",
			prob = 254
		},
		{
			param2 = 0,
			name = "gal:stone_brick",
			prob = 254
		},
		{
			param2 = 0,
			name = "gal:stone_brick",
			prob = 254
		},
		{
			param2 = 0,
			name = "gal:stone_brick",
			prob = 254
		},
		{
			param2 = 0,
			name = "gal:stone_brick",
			prob = 254
		},
		{
			param2 = 0,
			name = "gal:stone_brick",
			prob = 254
		},
		{
			param2 = 0,
			name = "gal:stone_brick",
			prob = 254
		},
		{
			param2 = 0,
			name = "gal:stone_brick",
			prob = 254
		},
		{
			param2 = 0,
			name = "gal:stone_brick",
			prob = 254
		},
		{
			param2 = 0,
			name = "gal:stone_brick",
			prob = 254
		},
		{
			param2 = 0,
			name = "gal:stone_brick",
			prob = 254
		},
		{
			param2 = 0,
			name = "gal:stone_brick",
			prob = 254
		}
	},
	size = {
		y = 1,
		x = 10,
		z = 3
	}
}